{"expireTime":9007200882776291000,"key":"gatsby-plugin-mdx-entire-payload-7fca249a0ed0048c3483b8e8c177d009-/funycode-undefined","val":{"mdast":{"type":"root","children":[{"type":"heading","depth":1,"children":[{"type":"text","value":"Try-catch Statement in Java","position":{"start":{"line":1,"column":3,"offset":2},"end":{"line":1,"column":30,"offset":29},"indent":[]}}],"position":{"start":{"line":1,"column":1,"offset":0},"end":{"line":1,"column":30,"offset":29},"indent":[]}},{"type":"paragraph","children":[{"type":"text","value":"The purpose of exception handling mechanism is to provide a means to detect and report an “exceptional circumstance” so that appropriate action can be taken. The mechanism suggests incorporation of a separate error handling code that performs the following tasks:","position":{"start":{"line":2,"column":1,"offset":31},"end":{"line":2,"column":264,"offset":294},"indent":[]}}],"position":{"start":{"line":2,"column":1,"offset":31},"end":{"line":2,"column":264,"offset":294},"indent":[]}},{"type":"list","ordered":true,"start":1,"spread":false,"children":[{"type":"listItem","spread":false,"checked":null,"children":[{"type":"paragraph","children":[{"type":"text","value":"Find the problem (Hit the exception).","position":{"start":{"line":4,"column":4,"offset":301},"end":{"line":4,"column":41,"offset":338},"indent":[]}}],"position":{"start":{"line":4,"column":4,"offset":301},"end":{"line":4,"column":41,"offset":338},"indent":[]}}],"position":{"start":{"line":4,"column":1,"offset":298},"end":{"line":4,"column":41,"offset":338},"indent":[]}},{"type":"listItem","spread":false,"checked":null,"children":[{"type":"paragraph","children":[{"type":"text","value":"Inform that an error has occurred (Throw the exception)","position":{"start":{"line":5,"column":4,"offset":343},"end":{"line":5,"column":59,"offset":398},"indent":[]}}],"position":{"start":{"line":5,"column":4,"offset":343},"end":{"line":5,"column":59,"offset":398},"indent":[]}}],"position":{"start":{"line":5,"column":1,"offset":340},"end":{"line":5,"column":59,"offset":398},"indent":[]}},{"type":"listItem","spread":false,"checked":null,"children":[{"type":"paragraph","children":[{"type":"text","value":"Receive the error information (Catch the exception)","position":{"start":{"line":6,"column":4,"offset":403},"end":{"line":6,"column":55,"offset":454},"indent":[]}}],"position":{"start":{"line":6,"column":4,"offset":403},"end":{"line":6,"column":55,"offset":454},"indent":[]}}],"position":{"start":{"line":6,"column":1,"offset":400},"end":{"line":6,"column":55,"offset":454},"indent":[]}},{"type":"listItem","spread":false,"checked":null,"children":[{"type":"paragraph","children":[{"type":"text","value":"Take corrective actions (Handle the exception)\nThe error handling code basically consists of two segments, one to detect errors and to throw exceptions and the other to catch exceptions and to take appropriate actions.\n","position":{"start":{"line":7,"column":4,"offset":459},"end":{"line":9,"column":1,"offset":680},"indent":[1,1]}},{"type":"image","title":null,"url":"../../assets/javaPic/trycatch.png","alt":"Fig: try-catch block in Java ","position":{"start":{"line":9,"column":1,"offset":680},"end":{"line":9,"column":68,"offset":747},"indent":[]}}],"position":{"start":{"line":7,"column":4,"offset":459},"end":{"line":9,"column":68,"offset":747},"indent":[1,1]}}],"position":{"start":{"line":7,"column":1,"offset":456},"end":{"line":9,"column":68,"offset":747},"indent":[1,1]}}],"position":{"start":{"line":4,"column":1,"offset":298},"end":{"line":9,"column":68,"offset":747},"indent":[1,1,1,1,1]}},{"type":"list","ordered":false,"start":null,"spread":false,"children":[{"type":"listItem","spread":false,"checked":null,"children":[{"type":"paragraph","children":[{"type":"text","value":"Java exception handling is managed via five keywords: try, catch, throw, throws, finally.","position":{"start":{"line":10,"column":3,"offset":751},"end":{"line":10,"column":92,"offset":840},"indent":[]}}],"position":{"start":{"line":10,"column":3,"offset":751},"end":{"line":10,"column":92,"offset":840},"indent":[]}}],"position":{"start":{"line":10,"column":1,"offset":749},"end":{"line":10,"column":92,"offset":840},"indent":[]}},{"type":"listItem","spread":false,"checked":null,"children":[{"type":"paragraph","children":[{"type":"text","value":"Program statements that you want to monitor for exceptions are contained within a try block.","position":{"start":{"line":11,"column":3,"offset":844},"end":{"line":11,"column":95,"offset":936},"indent":[]}}],"position":{"start":{"line":11,"column":3,"offset":844},"end":{"line":11,"column":95,"offset":936},"indent":[]}}],"position":{"start":{"line":11,"column":1,"offset":842},"end":{"line":11,"column":95,"offset":936},"indent":[]}},{"type":"listItem","spread":false,"checked":null,"children":[{"type":"paragraph","children":[{"type":"text","value":"If an exception occurs within the try block, it is thrown. Your code can catch this exception (using catch) and then throw it in some rational manner.","position":{"start":{"line":12,"column":3,"offset":940},"end":{"line":12,"column":153,"offset":1090},"indent":[]}}],"position":{"start":{"line":12,"column":3,"offset":940},"end":{"line":12,"column":153,"offset":1090},"indent":[]}}],"position":{"start":{"line":12,"column":1,"offset":938},"end":{"line":12,"column":153,"offset":1090},"indent":[]}},{"type":"listItem","spread":false,"checked":null,"children":[{"type":"paragraph","children":[{"type":"text","value":"System-generated exceptions are automatically thrown by Java run-time system.","position":{"start":{"line":13,"column":3,"offset":1094},"end":{"line":13,"column":80,"offset":1171},"indent":[]}}],"position":{"start":{"line":13,"column":3,"offset":1094},"end":{"line":13,"column":80,"offset":1171},"indent":[]}}],"position":{"start":{"line":13,"column":1,"offset":1092},"end":{"line":13,"column":80,"offset":1171},"indent":[]}},{"type":"listItem","spread":false,"checked":null,"children":[{"type":"paragraph","children":[{"type":"text","value":"To manually throw an exception, use the keyword throw; Any exception that is thrown out of a method must be specified as such by a throws clause.","position":{"start":{"line":14,"column":3,"offset":1175},"end":{"line":14,"column":148,"offset":1320},"indent":[]}}],"position":{"start":{"line":14,"column":3,"offset":1175},"end":{"line":14,"column":148,"offset":1320},"indent":[]}}],"position":{"start":{"line":14,"column":1,"offset":1173},"end":{"line":14,"column":148,"offset":1320},"indent":[]}},{"type":"listItem","spread":false,"checked":null,"children":[{"type":"paragraph","children":[{"type":"text","value":"Any code that absolutely must be executed before a method returns is put in finally block.","position":{"start":{"line":15,"column":3,"offset":1324},"end":{"line":15,"column":93,"offset":1414},"indent":[]}}],"position":{"start":{"line":15,"column":3,"offset":1324},"end":{"line":15,"column":93,"offset":1414},"indent":[]}}],"position":{"start":{"line":15,"column":1,"offset":1322},"end":{"line":15,"column":93,"offset":1414},"indent":[]}}],"position":{"start":{"line":10,"column":1,"offset":749},"end":{"line":15,"column":93,"offset":1414},"indent":[1,1,1,1,1]}},{"type":"heading","depth":2,"children":[{"type":"text","value":"Java Exception Keywords","position":{"start":{"line":16,"column":4,"offset":1419},"end":{"line":16,"column":27,"offset":1442},"indent":[]}}],"position":{"start":{"line":16,"column":1,"offset":1416},"end":{"line":16,"column":27,"offset":1442},"indent":[]}},{"type":"heading","depth":3,"children":[{"type":"text","value":"try","position":{"start":{"line":17,"column":5,"offset":1448},"end":{"line":17,"column":8,"offset":1451},"indent":[]}}],"position":{"start":{"line":17,"column":1,"offset":1444},"end":{"line":17,"column":8,"offset":1451},"indent":[]}},{"type":"list","ordered":false,"start":null,"spread":false,"children":[{"type":"listItem","spread":false,"checked":null,"children":[{"type":"paragraph","children":[{"type":"text","value":"The try block contains set of statements where an exception can occur.","position":{"start":{"line":18,"column":3,"offset":1455},"end":{"line":18,"column":73,"offset":1525},"indent":[]}}],"position":{"start":{"line":18,"column":3,"offset":1455},"end":{"line":18,"column":73,"offset":1525},"indent":[]}}],"position":{"start":{"line":18,"column":1,"offset":1453},"end":{"line":18,"column":73,"offset":1525},"indent":[]}},{"type":"listItem","spread":false,"checked":null,"children":[{"type":"paragraph","children":[{"type":"text","value":"A try block is always followed by a catch block, which handles the exception that occurs in associated try block.","position":{"start":{"line":19,"column":3,"offset":1529},"end":{"line":19,"column":116,"offset":1642},"indent":[]}}],"position":{"start":{"line":19,"column":3,"offset":1529},"end":{"line":19,"column":116,"offset":1642},"indent":[]}}],"position":{"start":{"line":19,"column":1,"offset":1527},"end":{"line":19,"column":116,"offset":1642},"indent":[]}},{"type":"listItem","spread":false,"checked":null,"children":[{"type":"paragraph","children":[{"type":"text","value":"A try block must be followed by catch blocks or finally block or both.","position":{"start":{"line":20,"column":3,"offset":1646},"end":{"line":20,"column":73,"offset":1716},"indent":[]}}],"position":{"start":{"line":20,"column":3,"offset":1646},"end":{"line":20,"column":73,"offset":1716},"indent":[]}}],"position":{"start":{"line":20,"column":1,"offset":1644},"end":{"line":20,"column":73,"offset":1716},"indent":[]}}],"position":{"start":{"line":18,"column":1,"offset":1453},"end":{"line":20,"column":73,"offset":1716},"indent":[1,1]}},{"type":"heading","depth":3,"children":[{"type":"text","value":"catch","position":{"start":{"line":21,"column":5,"offset":1722},"end":{"line":21,"column":10,"offset":1727},"indent":[]}}],"position":{"start":{"line":21,"column":1,"offset":1718},"end":{"line":21,"column":10,"offset":1727},"indent":[]}},{"type":"list","ordered":false,"start":null,"spread":false,"children":[{"type":"listItem","spread":false,"checked":null,"children":[{"type":"paragraph","children":[{"type":"text","value":"A catch block is where you handle the exceptions, this block must follow the try block.","position":{"start":{"line":22,"column":3,"offset":1731},"end":{"line":22,"column":90,"offset":1818},"indent":[]}}],"position":{"start":{"line":22,"column":3,"offset":1731},"end":{"line":22,"column":90,"offset":1818},"indent":[]}}],"position":{"start":{"line":22,"column":1,"offset":1729},"end":{"line":22,"column":90,"offset":1818},"indent":[]}},{"type":"listItem","spread":false,"checked":null,"children":[{"type":"paragraph","children":[{"type":"text","value":"A single try block can have several catch blocks associated with it.","position":{"start":{"line":23,"column":3,"offset":1822},"end":{"line":23,"column":71,"offset":1890},"indent":[]}}],"position":{"start":{"line":23,"column":3,"offset":1822},"end":{"line":23,"column":71,"offset":1890},"indent":[]}}],"position":{"start":{"line":23,"column":1,"offset":1820},"end":{"line":23,"column":71,"offset":1890},"indent":[]}},{"type":"listItem","spread":false,"checked":null,"children":[{"type":"paragraph","children":[{"type":"text","value":"You can catch different exceptions in different catch blocks.","position":{"start":{"line":24,"column":3,"offset":1894},"end":{"line":24,"column":64,"offset":1955},"indent":[]}}],"position":{"start":{"line":24,"column":3,"offset":1894},"end":{"line":24,"column":64,"offset":1955},"indent":[]}}],"position":{"start":{"line":24,"column":1,"offset":1892},"end":{"line":24,"column":64,"offset":1955},"indent":[]}},{"type":"listItem","spread":false,"checked":null,"children":[{"type":"paragraph","children":[{"type":"text","value":"When an exception occurs in try block, the corresponding catch block that handles that particular exception executes.","position":{"start":{"line":25,"column":3,"offset":1959},"end":{"line":25,"column":120,"offset":2076},"indent":[]}}],"position":{"start":{"line":25,"column":3,"offset":1959},"end":{"line":25,"column":120,"offset":2076},"indent":[]}}],"position":{"start":{"line":25,"column":1,"offset":1957},"end":{"line":25,"column":120,"offset":2076},"indent":[]}},{"type":"listItem","spread":false,"checked":null,"children":[{"type":"paragraph","children":[{"type":"text","value":"For example if an arithmetic exception occurs in try block then the statements enclosed in catch block for arithmetic exception executes.","position":{"start":{"line":26,"column":3,"offset":2080},"end":{"line":26,"column":140,"offset":2217},"indent":[]}}],"position":{"start":{"line":26,"column":3,"offset":2080},"end":{"line":26,"column":140,"offset":2217},"indent":[]}}],"position":{"start":{"line":26,"column":1,"offset":2078},"end":{"line":26,"column":140,"offset":2217},"indent":[]}}],"position":{"start":{"line":22,"column":1,"offset":1729},"end":{"line":26,"column":140,"offset":2217},"indent":[1,1,1,1]}},{"type":"heading","depth":3,"children":[{"type":"text","value":"finally","position":{"start":{"line":27,"column":5,"offset":2223},"end":{"line":27,"column":12,"offset":2230},"indent":[]}}],"position":{"start":{"line":27,"column":1,"offset":2219},"end":{"line":27,"column":12,"offset":2230},"indent":[]}},{"type":"list","ordered":false,"start":null,"spread":false,"children":[{"type":"listItem","spread":false,"checked":null,"children":[{"type":"paragraph","children":[{"type":"text","value":"A finally block contains all the crucial statements that must be executed whether exception occurs or not.","position":{"start":{"line":28,"column":3,"offset":2234},"end":{"line":28,"column":109,"offset":2340},"indent":[]}}],"position":{"start":{"line":28,"column":3,"offset":2234},"end":{"line":28,"column":109,"offset":2340},"indent":[]}}],"position":{"start":{"line":28,"column":1,"offset":2232},"end":{"line":28,"column":109,"offset":2340},"indent":[]}},{"type":"listItem","spread":false,"checked":null,"children":[{"type":"paragraph","children":[{"type":"text","value":"The statements present in this block will always execute regardless of whether exception occurs in try block or not such as closing a connection, stream etc.","position":{"start":{"line":29,"column":3,"offset":2344},"end":{"line":29,"column":160,"offset":2501},"indent":[]}}],"position":{"start":{"line":29,"column":3,"offset":2344},"end":{"line":29,"column":160,"offset":2501},"indent":[]}}],"position":{"start":{"line":29,"column":1,"offset":2342},"end":{"line":29,"column":160,"offset":2501},"indent":[]}}],"position":{"start":{"line":28,"column":1,"offset":2232},"end":{"line":29,"column":160,"offset":2501},"indent":[1]}},{"type":"heading","depth":3,"children":[{"type":"text","value":"throw","position":{"start":{"line":30,"column":5,"offset":2507},"end":{"line":30,"column":10,"offset":2512},"indent":[]}}],"position":{"start":{"line":30,"column":1,"offset":2503},"end":{"line":30,"column":10,"offset":2512},"indent":[]}},{"type":"list","ordered":false,"start":null,"spread":false,"children":[{"type":"listItem","spread":false,"checked":null,"children":[{"type":"paragraph","children":[{"type":"text","value":"The “throw” keyword is used to throw an exception.","position":{"start":{"line":31,"column":3,"offset":2516},"end":{"line":31,"column":53,"offset":2566},"indent":[]}}],"position":{"start":{"line":31,"column":3,"offset":2516},"end":{"line":31,"column":53,"offset":2566},"indent":[]}}],"position":{"start":{"line":31,"column":1,"offset":2514},"end":{"line":31,"column":53,"offset":2566},"indent":[]}},{"type":"listItem","spread":false,"checked":null,"children":[{"type":"paragraph","children":[{"type":"text","value":"We can define our own set of conditions or rules and throw an exception explicitly using throw keyword.","position":{"start":{"line":32,"column":3,"offset":2570},"end":{"line":32,"column":106,"offset":2673},"indent":[]}}],"position":{"start":{"line":32,"column":3,"offset":2570},"end":{"line":32,"column":106,"offset":2673},"indent":[]}}],"position":{"start":{"line":32,"column":1,"offset":2568},"end":{"line":32,"column":106,"offset":2673},"indent":[]}},{"type":"listItem","spread":false,"checked":null,"children":[{"type":"paragraph","children":[{"type":"text","value":"For example, we can throw ArithmeticException when we divide number by 5, or any other numbers, what we need to do is just set the condition and throw any exception using throw keyword.","position":{"start":{"line":33,"column":3,"offset":2677},"end":{"line":33,"column":188,"offset":2862},"indent":[]}}],"position":{"start":{"line":33,"column":3,"offset":2677},"end":{"line":33,"column":188,"offset":2862},"indent":[]}}],"position":{"start":{"line":33,"column":1,"offset":2675},"end":{"line":33,"column":188,"offset":2862},"indent":[]}},{"type":"listItem","spread":false,"checked":null,"children":[{"type":"paragraph","children":[{"type":"text","value":"Throw keyword can also be used for throwing custom exceptions,","position":{"start":{"line":34,"column":3,"offset":2866},"end":{"line":34,"column":65,"offset":2928},"indent":[]}}],"position":{"start":{"line":34,"column":3,"offset":2866},"end":{"line":34,"column":65,"offset":2928},"indent":[]}}],"position":{"start":{"line":34,"column":1,"offset":2864},"end":{"line":34,"column":65,"offset":2928},"indent":[]}}],"position":{"start":{"line":31,"column":1,"offset":2514},"end":{"line":34,"column":65,"offset":2928},"indent":[1,1,1]}},{"type":"heading","depth":3,"children":[{"type":"text","value":"Throws","position":{"start":{"line":35,"column":5,"offset":2934},"end":{"line":35,"column":11,"offset":2940},"indent":[]}}],"position":{"start":{"line":35,"column":1,"offset":2930},"end":{"line":35,"column":11,"offset":2940},"indent":[]}},{"type":"list","ordered":false,"start":null,"spread":false,"children":[{"type":"listItem","spread":false,"checked":null,"children":[{"type":"paragraph","children":[{"type":"text","value":"The “throws” keyword is used to declare exceptions.","position":{"start":{"line":36,"column":3,"offset":2944},"end":{"line":36,"column":54,"offset":2995},"indent":[]}}],"position":{"start":{"line":36,"column":3,"offset":2944},"end":{"line":36,"column":54,"offset":2995},"indent":[]}}],"position":{"start":{"line":36,"column":1,"offset":2942},"end":{"line":36,"column":54,"offset":2995},"indent":[]}},{"type":"listItem","spread":false,"checked":null,"children":[{"type":"paragraph","children":[{"type":"text","value":"It doesn’t throw an exception.","position":{"start":{"line":37,"column":3,"offset":2999},"end":{"line":37,"column":33,"offset":3029},"indent":[]}}],"position":{"start":{"line":37,"column":3,"offset":2999},"end":{"line":37,"column":33,"offset":3029},"indent":[]}}],"position":{"start":{"line":37,"column":1,"offset":2997},"end":{"line":37,"column":33,"offset":3029},"indent":[]}},{"type":"listItem","spread":false,"checked":null,"children":[{"type":"paragraph","children":[{"type":"text","value":"It specifies that there may occur an exception in the method.","position":{"start":{"line":38,"column":3,"offset":3033},"end":{"line":38,"column":64,"offset":3094},"indent":[]}}],"position":{"start":{"line":38,"column":3,"offset":3033},"end":{"line":38,"column":64,"offset":3094},"indent":[]}}],"position":{"start":{"line":38,"column":1,"offset":3031},"end":{"line":38,"column":64,"offset":3094},"indent":[]}},{"type":"listItem","spread":false,"checked":null,"children":[{"type":"paragraph","children":[{"type":"text","value":"It is always used with method signature.","position":{"start":{"line":39,"column":3,"offset":3098},"end":{"line":39,"column":43,"offset":3138},"indent":[]}}],"position":{"start":{"line":39,"column":3,"offset":3098},"end":{"line":39,"column":43,"offset":3138},"indent":[]}}],"position":{"start":{"line":39,"column":1,"offset":3096},"end":{"line":39,"column":43,"offset":3138},"indent":[]}},{"type":"listItem","spread":false,"checked":null,"children":[{"type":"paragraph","children":[{"type":"text","value":"This is the general form of an exception-handling block","position":{"start":{"line":40,"column":3,"offset":3142},"end":{"line":40,"column":58,"offset":3197},"indent":[]}}],"position":{"start":{"line":40,"column":3,"offset":3142},"end":{"line":40,"column":58,"offset":3197},"indent":[]}}],"position":{"start":{"line":40,"column":1,"offset":3140},"end":{"line":40,"column":58,"offset":3197},"indent":[]}}],"position":{"start":{"line":36,"column":1,"offset":2942},"end":{"line":40,"column":58,"offset":3197},"indent":[1,1,1,1]}},{"type":"code","lang":"js","meta":null,"value":"try\n    {\n    // block of code to monitor for errors\n    }\ncatch (ExceptionTypel exOb)\n    {\n    // exception handler for ExceptionTypel\n    }catch (ExceptionType2 exOb)\n    {\n    // exception handler for ExceptionType2\n    }\n// . . . . . . . . .\nfinally\n    {\n    // block of code to be executed before try block ends\n    }","position":{"start":{"line":41,"column":1,"offset":3199},"end":{"line":58,"column":4,"offset":3550},"indent":[1,1,1,1,1,1,1,1,1,1,1,1,1,1,1,1,1]}},{"type":"heading","depth":2,"children":[{"type":"text","value":"Common Scenarios of Java Exceptions","position":{"start":{"line":59,"column":4,"offset":3555},"end":{"line":59,"column":39,"offset":3590},"indent":[]}}],"position":{"start":{"line":59,"column":1,"offset":3552},"end":{"line":59,"column":39,"offset":3590},"indent":[]}},{"type":"heading","depth":2,"children":[{"type":"text","value":"ArithmeticException","position":{"start":{"line":60,"column":4,"offset":3595},"end":{"line":60,"column":23,"offset":3614},"indent":[]}}],"position":{"start":{"line":60,"column":1,"offset":3592},"end":{"line":60,"column":23,"offset":3614},"indent":[]}},{"type":"code","lang":null,"meta":null,"value":"int a=50/0;//ArithmeticException","position":{"start":{"line":61,"column":1,"offset":3616},"end":{"line":63,"column":4,"offset":3658},"indent":[1,1]}},{"type":"heading","depth":2,"children":[{"type":"text","value":"NullPointerException","position":{"start":{"line":64,"column":4,"offset":3663},"end":{"line":64,"column":24,"offset":3683},"indent":[]}}],"position":{"start":{"line":64,"column":1,"offset":3660},"end":{"line":64,"column":24,"offset":3683},"indent":[]}},{"type":"code","lang":null,"meta":null,"value":"String s=null;\nSystem.out.println(s.length());//NullPointerException )","position":{"start":{"line":65,"column":1,"offset":3685},"end":{"line":68,"column":4,"offset":3766},"indent":[1,1,1]}},{"type":"heading","depth":2,"children":[{"type":"text","value":"NumberFormatException","position":{"start":{"line":69,"column":4,"offset":3771},"end":{"line":69,"column":25,"offset":3792},"indent":[]}}],"position":{"start":{"line":69,"column":1,"offset":3768},"end":{"line":69,"column":25,"offset":3792},"indent":[]}},{"type":"code","lang":null,"meta":null,"value":"String s=”abc”;\nint i=Integer.parseInt(s);//NumberFormatException","position":{"start":{"line":70,"column":1,"offset":3794},"end":{"line":73,"column":4,"offset":3870},"indent":[1,1,1]}},{"type":"heading","depth":2,"children":[{"type":"text","value":"ArrayIndexOutOfBoundsException","position":{"start":{"line":74,"column":4,"offset":3875},"end":{"line":74,"column":34,"offset":3905},"indent":[]}}],"position":{"start":{"line":74,"column":1,"offset":3872},"end":{"line":74,"column":34,"offset":3905},"indent":[]}},{"type":"code","lang":null,"meta":null,"value":"int a[]=new int[5];\na[10]=50; //ArrayIndexOutOfBoundsException","position":{"start":{"line":75,"column":1,"offset":3907},"end":{"line":78,"column":4,"offset":3980},"indent":[1,1,1]}},{"type":"heading","depth":2,"children":[{"type":"text","value":"Exception Handling Mechanism","position":{"start":{"line":79,"column":4,"offset":3985},"end":{"line":79,"column":32,"offset":4013},"indent":[]}}],"position":{"start":{"line":79,"column":1,"offset":3982},"end":{"line":79,"column":32,"offset":4013},"indent":[]}},{"type":"list","ordered":false,"start":null,"spread":true,"children":[{"type":"listItem","spread":false,"checked":null,"children":[{"type":"paragraph","children":[{"type":"text","value":"Default Exception Handling","position":{"start":{"line":80,"column":3,"offset":4017},"end":{"line":80,"column":29,"offset":4043},"indent":[]}}],"position":{"start":{"line":80,"column":3,"offset":4017},"end":{"line":80,"column":29,"offset":4043},"indent":[]}}],"position":{"start":{"line":80,"column":1,"offset":4015},"end":{"line":80,"column":29,"offset":4043},"indent":[]}},{"type":"listItem","spread":false,"checked":null,"children":[{"type":"paragraph","children":[{"type":"text","value":"Customized Exception Handling","position":{"start":{"line":81,"column":3,"offset":4047},"end":{"line":81,"column":32,"offset":4076},"indent":[]}}],"position":{"start":{"line":81,"column":3,"offset":4047},"end":{"line":81,"column":32,"offset":4076},"indent":[]}}],"position":{"start":{"line":81,"column":1,"offset":4045},"end":{"line":81,"column":32,"offset":4076},"indent":[]}},{"type":"listItem","spread":false,"checked":null,"children":[{"type":"paragraph","children":[{"type":"text","value":"Default Exception Handling","position":{"start":{"line":82,"column":3,"offset":4080},"end":{"line":82,"column":29,"offset":4106},"indent":[]}}],"position":{"start":{"line":82,"column":3,"offset":4080},"end":{"line":82,"column":29,"offset":4106},"indent":[]}}],"position":{"start":{"line":82,"column":1,"offset":4078},"end":{"line":83,"column":1,"offset":4108},"indent":[1]}},{"type":"listItem","spread":false,"checked":null,"children":[{"type":"paragraph","children":[{"type":"text","value":"Whenever inside a method, if an exception has occurred, the method creates an Object known as Exception Object and hands it off to the run-time system(JVM).","position":{"start":{"line":84,"column":3,"offset":4112},"end":{"line":84,"column":159,"offset":4268},"indent":[]}}],"position":{"start":{"line":84,"column":3,"offset":4112},"end":{"line":84,"column":159,"offset":4268},"indent":[]}}],"position":{"start":{"line":84,"column":1,"offset":4110},"end":{"line":84,"column":159,"offset":4268},"indent":[]}},{"type":"listItem","spread":false,"checked":null,"children":[{"type":"paragraph","children":[{"type":"text","value":"The exception object contains name and description of the exception, and current state of the program where exception has occurred.","position":{"start":{"line":85,"column":3,"offset":4272},"end":{"line":85,"column":134,"offset":4403},"indent":[]}}],"position":{"start":{"line":85,"column":3,"offset":4272},"end":{"line":85,"column":134,"offset":4403},"indent":[]}}],"position":{"start":{"line":85,"column":1,"offset":4270},"end":{"line":85,"column":134,"offset":4403},"indent":[]}},{"type":"listItem","spread":false,"checked":null,"children":[{"type":"paragraph","children":[{"type":"text","value":"Creating the Exception Object and handling it to the run-time system is called throwing an Exception.","position":{"start":{"line":86,"column":3,"offset":4407},"end":{"line":86,"column":104,"offset":4508},"indent":[]}}],"position":{"start":{"line":86,"column":3,"offset":4407},"end":{"line":86,"column":104,"offset":4508},"indent":[]}}],"position":{"start":{"line":86,"column":1,"offset":4405},"end":{"line":86,"column":104,"offset":4508},"indent":[]}},{"type":"listItem","spread":false,"checked":null,"children":[{"type":"paragraph","children":[{"type":"text","value":"There might be the list of the methods that had been called to get to the method where exception was occurred.","position":{"start":{"line":87,"column":3,"offset":4512},"end":{"line":87,"column":113,"offset":4622},"indent":[]}}],"position":{"start":{"line":87,"column":3,"offset":4512},"end":{"line":87,"column":113,"offset":4622},"indent":[]}}],"position":{"start":{"line":87,"column":1,"offset":4510},"end":{"line":87,"column":113,"offset":4622},"indent":[]}},{"type":"listItem","spread":false,"checked":null,"children":[{"type":"paragraph","children":[{"type":"text","value":"This ordered list of the methods is called Call Stack","position":{"start":{"line":88,"column":3,"offset":4626},"end":{"line":88,"column":56,"offset":4679},"indent":[]}}],"position":{"start":{"line":88,"column":3,"offset":4626},"end":{"line":88,"column":56,"offset":4679},"indent":[]}}],"position":{"start":{"line":88,"column":1,"offset":4624},"end":{"line":88,"column":56,"offset":4679},"indent":[]}}],"position":{"start":{"line":80,"column":1,"offset":4015},"end":{"line":88,"column":56,"offset":4679},"indent":[1,1,1,1,1,1,1,1]}},{"type":"heading","depth":3,"children":[{"type":"text","value":"Example-1: Write a java program to illustrate how default exception is thrown.","position":{"start":{"line":89,"column":5,"offset":4685},"end":{"line":89,"column":83,"offset":4763},"indent":[]}}],"position":{"start":{"line":89,"column":1,"offset":4681},"end":{"line":89,"column":83,"offset":4763},"indent":[]}},{"type":"code","lang":"js","meta":null,"value":"//Write a java program to illustrate how default exception is thrown.\npublic class FunyCodeException {\n    public static void main(String[] args) {\n    String s=null;\n    System.out.println(s.length());\n   }\n }\nOutput:\nException in thread \"main\" java.lang.NullPointerException: Cannot invoke \"String.length()\" because \"s\" is null at FunyCodeException.main(FunyCodeException.java:6)","position":{"start":{"line":90,"column":1,"offset":4765},"end":{"line":100,"column":4,"offset":5166},"indent":[1,1,1,1,1,1,1,1,1,1]}},{"type":"heading","depth":2,"children":[{"type":"text","value":"Customized Exception Handling","position":{"start":{"line":101,"column":4,"offset":5171},"end":{"line":101,"column":33,"offset":5200},"indent":[]}}],"position":{"start":{"line":101,"column":1,"offset":5168},"end":{"line":101,"column":33,"offset":5200},"indent":[]}},{"type":"list","ordered":false,"start":null,"spread":false,"children":[{"type":"listItem","spread":false,"checked":null,"children":[{"type":"paragraph","children":[{"type":"text","value":"Java exception handling is managed via five keywords: try, catch, throw, throws, and finally.","position":{"start":{"line":102,"column":3,"offset":5204},"end":{"line":102,"column":96,"offset":5297},"indent":[]}}],"position":{"start":{"line":102,"column":3,"offset":5204},"end":{"line":102,"column":96,"offset":5297},"indent":[]}}],"position":{"start":{"line":102,"column":1,"offset":5202},"end":{"line":102,"column":96,"offset":5297},"indent":[]}},{"type":"listItem","spread":false,"checked":null,"children":[{"type":"paragraph","children":[{"type":"text","value":"Program statements that you think can raise exceptions are contained within a try block. If an exception occurs within the try block, it is thrown.","position":{"start":{"line":103,"column":3,"offset":5301},"end":{"line":103,"column":150,"offset":5448},"indent":[]}}],"position":{"start":{"line":103,"column":3,"offset":5301},"end":{"line":103,"column":150,"offset":5448},"indent":[]}}],"position":{"start":{"line":103,"column":1,"offset":5299},"end":{"line":103,"column":150,"offset":5448},"indent":[]}},{"type":"listItem","spread":false,"checked":null,"children":[{"type":"paragraph","children":[{"type":"text","value":"Your code can catch this exception (using catch block) and handle it in some rational manner.","position":{"start":{"line":104,"column":3,"offset":5452},"end":{"line":104,"column":96,"offset":5545},"indent":[]}}],"position":{"start":{"line":104,"column":3,"offset":5452},"end":{"line":104,"column":96,"offset":5545},"indent":[]}}],"position":{"start":{"line":104,"column":1,"offset":5450},"end":{"line":104,"column":96,"offset":5545},"indent":[]}},{"type":"listItem","spread":false,"checked":null,"children":[{"type":"paragraph","children":[{"type":"text","value":"System-generated exceptions are automatically thrown by the Java run-time system.","position":{"start":{"line":105,"column":3,"offset":5549},"end":{"line":105,"column":84,"offset":5630},"indent":[]}}],"position":{"start":{"line":105,"column":3,"offset":5549},"end":{"line":105,"column":84,"offset":5630},"indent":[]}}],"position":{"start":{"line":105,"column":1,"offset":5547},"end":{"line":105,"column":84,"offset":5630},"indent":[]}},{"type":"listItem","spread":false,"checked":null,"children":[{"type":"paragraph","children":[{"type":"text","value":"To manually throw an exception, use the keyword throw.","position":{"start":{"line":106,"column":3,"offset":5634},"end":{"line":106,"column":57,"offset":5688},"indent":[]}}],"position":{"start":{"line":106,"column":3,"offset":5634},"end":{"line":106,"column":57,"offset":5688},"indent":[]}}],"position":{"start":{"line":106,"column":1,"offset":5632},"end":{"line":106,"column":57,"offset":5688},"indent":[]}},{"type":"listItem","spread":false,"checked":null,"children":[{"type":"paragraph","children":[{"type":"text","value":"Any exception that is thrown out of a method must be specified as such by a throws clause.","position":{"start":{"line":107,"column":3,"offset":5692},"end":{"line":107,"column":93,"offset":5782},"indent":[]}}],"position":{"start":{"line":107,"column":3,"offset":5692},"end":{"line":107,"column":93,"offset":5782},"indent":[]}}],"position":{"start":{"line":107,"column":1,"offset":5690},"end":{"line":107,"column":93,"offset":5782},"indent":[]}},{"type":"listItem","spread":false,"checked":null,"children":[{"type":"paragraph","children":[{"type":"text","value":"Any code that absolutely must be executed after a try block completes is put in a finally block.","position":{"start":{"line":108,"column":3,"offset":5786},"end":{"line":108,"column":99,"offset":5882},"indent":[]}}],"position":{"start":{"line":108,"column":3,"offset":5786},"end":{"line":108,"column":99,"offset":5882},"indent":[]}}],"position":{"start":{"line":108,"column":1,"offset":5784},"end":{"line":108,"column":99,"offset":5882},"indent":[]}}],"position":{"start":{"line":102,"column":1,"offset":5202},"end":{"line":108,"column":99,"offset":5882},"indent":[1,1,1,1,1,1]}},{"type":"heading","depth":3,"children":[{"type":"text","value":"Example-2: Write a java program to illustrate simple exception using try catch block.","position":{"start":{"line":110,"column":5,"offset":5890},"end":{"line":110,"column":90,"offset":5975},"indent":[]}}],"position":{"start":{"line":110,"column":1,"offset":5886},"end":{"line":110,"column":90,"offset":5975},"indent":[]}},{"type":"code","lang":"js","meta":null,"value":"//Write a java program to illustrate simple exception using try catch block.\npublic class FunyCodeException {\n    public static void main(String[] args) {\n    try {\n      int a=100,b=0;\n      System.out.println(a/b);\n    }\n    catch(Exception e) {\n      System.out.println(e);\n    }\n  System.out.println(\"Rest of the code\");\n  }\n }","position":{"start":{"line":111,"column":1,"offset":5977},"end":{"line":125,"column":4,"offset":6332},"indent":[1,1,1,1,1,1,1,1,1,1,1,1,1,1]}},{"type":"code","lang":null,"meta":null,"value":"Output:\njava.lang.ArithmeticException: / by zero\nRest of the code","position":{"start":{"line":126,"column":1,"offset":6334},"end":{"line":130,"column":4,"offset":6411},"indent":[1,1,1,1]}},{"type":"heading","depth":3,"children":[{"type":"text","value":"Example-3: Write a java program to illustrate null pointer exception using try catch block.","position":{"start":{"line":132,"column":5,"offset":6419},"end":{"line":132,"column":96,"offset":6510},"indent":[]}}],"position":{"start":{"line":132,"column":1,"offset":6415},"end":{"line":132,"column":96,"offset":6510},"indent":[]}},{"type":"code","lang":"js","meta":null,"value":"//Write a java program to illustrate null pointer exception using try catch block.\npublic class FunyCodeException {\n  public static void main(String[] args) {\n    try {\n      String s=null;\n      System.out.println(s.length());\n      }\n    catch(NullPointerException e) {\n      System.out.println(e);\n     }\n      System.out.println(\"Rest of the code\");\n     }\n   }","position":{"start":{"line":133,"column":1,"offset":6512},"end":{"line":147,"column":4,"offset":6901},"indent":[1,1,1,1,1,1,1,1,1,1,1,1,1,1]}},{"type":"code","lang":null,"meta":null,"value":"Output:\njava.lang.NullPointerException: Cannot invoke \"String.length()\" because \"s\" is null\nRest of the code","position":{"start":{"line":148,"column":1,"offset":6903},"end":{"line":152,"column":4,"offset":7023},"indent":[1,1,1,1]}},{"type":"heading","depth":2,"children":[{"type":"text","value":"Multiple Catch Blocks in Java","position":{"start":{"line":153,"column":4,"offset":7028},"end":{"line":153,"column":33,"offset":7057},"indent":[]}}],"position":{"start":{"line":153,"column":1,"offset":7025},"end":{"line":153,"column":33,"offset":7057},"indent":[]}},{"type":"list","ordered":false,"start":null,"spread":false,"children":[{"type":"listItem","spread":false,"checked":null,"children":[{"type":"paragraph","children":[{"type":"text","value":"A single try block can have any number of catch blocks.","position":{"start":{"line":154,"column":3,"offset":7061},"end":{"line":154,"column":58,"offset":7116},"indent":[]}}],"position":{"start":{"line":154,"column":3,"offset":7061},"end":{"line":154,"column":58,"offset":7116},"indent":[]}}],"position":{"start":{"line":154,"column":1,"offset":7059},"end":{"line":154,"column":58,"offset":7116},"indent":[]}},{"type":"listItem","spread":false,"checked":null,"children":[{"type":"paragraph","children":[{"type":"text","value":"A generic catch block can handle all the exceptions. Whether it is","position":{"start":{"line":155,"column":3,"offset":7120},"end":{"line":155,"column":69,"offset":7186},"indent":[]}}],"position":{"start":{"line":155,"column":3,"offset":7120},"end":{"line":155,"column":69,"offset":7186},"indent":[]}}],"position":{"start":{"line":155,"column":1,"offset":7118},"end":{"line":155,"column":69,"offset":7186},"indent":[]}},{"type":"listItem","spread":false,"checked":null,"children":[{"type":"paragraph","children":[{"type":"text","value":"ArrayIndexOutOfBoundsException or ArithmeticException or NullPointerException or any other type of exception","position":{"start":{"line":156,"column":3,"offset":7190},"end":{"line":156,"column":111,"offset":7298},"indent":[]}}],"position":{"start":{"line":156,"column":3,"offset":7190},"end":{"line":156,"column":111,"offset":7298},"indent":[]}}],"position":{"start":{"line":156,"column":1,"offset":7188},"end":{"line":156,"column":111,"offset":7298},"indent":[]}}],"position":{"start":{"line":154,"column":1,"offset":7059},"end":{"line":156,"column":111,"offset":7298},"indent":[1,1]}},{"type":"code","lang":null,"meta":null,"value":"catch(Exception e){\n//This catch block catches all the exceptions\n}","position":{"start":{"line":157,"column":1,"offset":7300},"end":{"line":161,"column":4,"offset":7379},"indent":[1,1,1,1]}},{"type":"list","ordered":false,"start":null,"spread":false,"children":[{"type":"listItem","spread":false,"checked":null,"children":[{"type":"paragraph","children":[{"type":"text","value":"If no exception occurs in try block then the catch blocks are completely ignored.","position":{"start":{"line":162,"column":3,"offset":7383},"end":{"line":162,"column":84,"offset":7464},"indent":[]}}],"position":{"start":{"line":162,"column":3,"offset":7383},"end":{"line":162,"column":84,"offset":7464},"indent":[]}}],"position":{"start":{"line":162,"column":1,"offset":7381},"end":{"line":162,"column":84,"offset":7464},"indent":[]}},{"type":"listItem","spread":false,"checked":null,"children":[{"type":"paragraph","children":[{"type":"text","value":"Corresponding catch blocks execute for that specific type of exception:","position":{"start":{"line":163,"column":3,"offset":7468},"end":{"line":163,"column":74,"offset":7539},"indent":[]}}],"position":{"start":{"line":163,"column":3,"offset":7468},"end":{"line":163,"column":74,"offset":7539},"indent":[]}}],"position":{"start":{"line":163,"column":1,"offset":7466},"end":{"line":163,"column":74,"offset":7539},"indent":[]}},{"type":"listItem","spread":false,"checked":null,"children":[{"type":"paragraph","children":[{"type":"text","value":"catch(ArithmeticException e) is a catch block that can hanlde ArithmeticException","position":{"start":{"line":164,"column":3,"offset":7543},"end":{"line":164,"column":84,"offset":7624},"indent":[]}}],"position":{"start":{"line":164,"column":3,"offset":7543},"end":{"line":164,"column":84,"offset":7624},"indent":[]}}],"position":{"start":{"line":164,"column":1,"offset":7541},"end":{"line":164,"column":84,"offset":7624},"indent":[]}},{"type":"listItem","spread":false,"checked":null,"children":[{"type":"paragraph","children":[{"type":"text","value":"catch(NullPointerException e) is a catch block that can handle NullPointerException","position":{"start":{"line":165,"column":3,"offset":7628},"end":{"line":165,"column":86,"offset":7711},"indent":[]}}],"position":{"start":{"line":165,"column":3,"offset":7628},"end":{"line":165,"column":86,"offset":7711},"indent":[]}}],"position":{"start":{"line":165,"column":1,"offset":7626},"end":{"line":165,"column":86,"offset":7711},"indent":[]}}],"position":{"start":{"line":162,"column":1,"offset":7381},"end":{"line":165,"column":86,"offset":7711},"indent":[1,1,1]}},{"type":"heading","depth":3,"children":[{"type":"text","value":"Example-4: Write a java program to illustrate multiple catch block in single try block.","position":{"start":{"line":166,"column":5,"offset":7717},"end":{"line":166,"column":92,"offset":7804},"indent":[]}}],"position":{"start":{"line":166,"column":1,"offset":7713},"end":{"line":166,"column":92,"offset":7804},"indent":[]}},{"type":"code","lang":"js","meta":null,"value":"//Write a java program to illustrate multiple catch block in single try block.\n  public class FunyCodeException {\n    public static void main(String[] args) {\n      try {\n        String s=null;\n        System.out.println(s.length());\n       }\n    catch(ArithmeticException e) {\n        System.out.println(\"Here Arithmetic Exception\");\n    }\n    catch(ArrayIndexOutOfBoundsException e) {\n        System.out.println(\"Here Array Index Out O fBounds Exception\");\n    }\n    catch(NumberFormatException e) {\n        System.out.println(\"Here Number Format Exception\");\n    }\n    catch(NullPointerException e) {\n        System.out.println(\"Here Null Pointer Exception\");\n    }\n    catch(Exception e) {\n        System.out.println(\"Other Exception\");\n    }\n        System.out.println(\"Rest of the code\");\n    }\n  }","position":{"start":{"line":167,"column":1,"offset":7806},"end":{"line":193,"column":4,"offset":8646},"indent":[1,1,1,1,1,1,1,1,1,1,1,1,1,1,1,1,1,1,1,1,1,1,1,1,1,1]}},{"type":"code","lang":null,"meta":null,"value":"Output:\nHere Null Pointer Exception\nRest of the code\nFinally Block","position":{"start":{"line":194,"column":1,"offset":8648},"end":{"line":199,"column":4,"offset":8727},"indent":[1,1,1,1,1]}},{"type":"list","ordered":false,"start":null,"spread":false,"children":[{"type":"listItem","spread":false,"checked":null,"children":[{"type":"paragraph","children":[{"type":"text","value":"A finally block must be associated with a try block, you cannot use finally without a try block.","position":{"start":{"line":200,"column":3,"offset":8731},"end":{"line":200,"column":99,"offset":8827},"indent":[]}}],"position":{"start":{"line":200,"column":3,"offset":8731},"end":{"line":200,"column":99,"offset":8827},"indent":[]}}],"position":{"start":{"line":200,"column":1,"offset":8729},"end":{"line":200,"column":99,"offset":8827},"indent":[]}},{"type":"listItem","spread":false,"checked":null,"children":[{"type":"paragraph","children":[{"type":"text","value":"You should place those statements in this block that must be executed always.","position":{"start":{"line":201,"column":3,"offset":8831},"end":{"line":201,"column":80,"offset":8908},"indent":[]}}],"position":{"start":{"line":201,"column":3,"offset":8831},"end":{"line":201,"column":80,"offset":8908},"indent":[]}}],"position":{"start":{"line":201,"column":1,"offset":8829},"end":{"line":201,"column":80,"offset":8908},"indent":[]}},{"type":"listItem","spread":false,"checked":null,"children":[{"type":"paragraph","children":[{"type":"text","value":"Finally block is optional, a try-catch block is sufficient for exception handling, however if you place a finally block then it will always run after the execution of try block.","position":{"start":{"line":202,"column":3,"offset":8912},"end":{"line":202,"column":180,"offset":9089},"indent":[]}}],"position":{"start":{"line":202,"column":3,"offset":8912},"end":{"line":202,"column":180,"offset":9089},"indent":[]}}],"position":{"start":{"line":202,"column":1,"offset":8910},"end":{"line":202,"column":180,"offset":9089},"indent":[]}},{"type":"listItem","spread":false,"checked":null,"children":[{"type":"paragraph","children":[{"type":"text","value":"In normal case when there is no exception in try block then the finally block is executed after try block.","position":{"start":{"line":203,"column":3,"offset":9093},"end":{"line":203,"column":109,"offset":9199},"indent":[]}}],"position":{"start":{"line":203,"column":3,"offset":9093},"end":{"line":203,"column":109,"offset":9199},"indent":[]}}],"position":{"start":{"line":203,"column":1,"offset":9091},"end":{"line":203,"column":109,"offset":9199},"indent":[]}},{"type":"listItem","spread":false,"checked":null,"children":[{"type":"paragraph","children":[{"type":"text","value":"However if an exception occurs then the catch block is executed before finally block.","position":{"start":{"line":204,"column":3,"offset":9203},"end":{"line":204,"column":88,"offset":9288},"indent":[]}}],"position":{"start":{"line":204,"column":3,"offset":9203},"end":{"line":204,"column":88,"offset":9288},"indent":[]}}],"position":{"start":{"line":204,"column":1,"offset":9201},"end":{"line":204,"column":88,"offset":9288},"indent":[]}},{"type":"listItem","spread":false,"checked":null,"children":[{"type":"paragraph","children":[{"type":"text","value":"An exception in the finally block, behaves exactly like any other exception.","position":{"start":{"line":205,"column":3,"offset":9292},"end":{"line":205,"column":79,"offset":9368},"indent":[]}}],"position":{"start":{"line":205,"column":3,"offset":9292},"end":{"line":205,"column":79,"offset":9368},"indent":[]}}],"position":{"start":{"line":205,"column":1,"offset":9290},"end":{"line":205,"column":79,"offset":9368},"indent":[]}},{"type":"listItem","spread":false,"checked":null,"children":[{"type":"paragraph","children":[{"type":"text","value":"The statements present in the finally block execute even if the try block contains control transfer statements like return, break or continue.","position":{"start":{"line":206,"column":3,"offset":9372},"end":{"line":206,"column":145,"offset":9514},"indent":[]}}],"position":{"start":{"line":206,"column":3,"offset":9372},"end":{"line":206,"column":145,"offset":9514},"indent":[]}}],"position":{"start":{"line":206,"column":1,"offset":9370},"end":{"line":206,"column":145,"offset":9514},"indent":[]}},{"type":"listItem","spread":false,"checked":null,"children":[{"type":"paragraph","children":[{"type":"text","value":"A try-finally block is possible without catch block.","position":{"start":{"line":207,"column":3,"offset":9518},"end":{"line":207,"column":55,"offset":9570},"indent":[]}}],"position":{"start":{"line":207,"column":3,"offset":9518},"end":{"line":207,"column":55,"offset":9570},"indent":[]}}],"position":{"start":{"line":207,"column":1,"offset":9516},"end":{"line":207,"column":55,"offset":9570},"indent":[]}},{"type":"listItem","spread":false,"checked":null,"children":[{"type":"paragraph","children":[{"type":"text","value":"Which means a try block can be used with finally without having a catch block.","position":{"start":{"line":208,"column":3,"offset":9574},"end":{"line":208,"column":81,"offset":9652},"indent":[]}}],"position":{"start":{"line":208,"column":3,"offset":9574},"end":{"line":208,"column":81,"offset":9652},"indent":[]}}],"position":{"start":{"line":208,"column":1,"offset":9572},"end":{"line":208,"column":81,"offset":9652},"indent":[]}}],"position":{"start":{"line":200,"column":1,"offset":8729},"end":{"line":208,"column":81,"offset":9652},"indent":[1,1,1,1,1,1,1,1]}},{"type":"heading","depth":3,"children":[{"type":"text","value":"Example-5: Write a Java program to illustrate finally block with try catch block.","position":{"start":{"line":210,"column":5,"offset":9660},"end":{"line":210,"column":86,"offset":9741},"indent":[]}}],"position":{"start":{"line":210,"column":1,"offset":9656},"end":{"line":210,"column":86,"offset":9741},"indent":[]}},{"type":"code","lang":"js","meta":null,"value":"//Write a Java program to illustrate finally block with try catch block.\n  public class FunyCodeException {\n    public static void main(String[] args) {\n     try {\n        String s=null;\n        System.out.println(s.length());\n    }\n    catch(NullPointerException e) {\n        System.out.println(\"Here NullPointer Exception\");\n    }\n    //this block will execute alaways either exception or not\n    finally {\n        System.out.println(\"I am from finally block\");\n    }\n        System.out.println(\"Rest of the code\");\n    }\n  }","position":{"start":{"line":211,"column":1,"offset":9743},"end":{"line":229,"column":4,"offset":10298},"indent":[1,1,1,1,1,1,1,1,1,1,1,1,1,1,1,1,1,1]}},{"type":"code","lang":null,"meta":null,"value":"Output:\nHere NullPointer Exception\nI am from finally block\nRest of the code","position":{"start":{"line":230,"column":1,"offset":10300},"end":{"line":235,"column":4,"offset":10388},"indent":[1,1,1,1,1]}},{"type":"heading","depth":3,"children":[{"type":"text","value":"Example-6: Write a Java program to illustrate finally block with return statement in try block.","position":{"start":{"line":236,"column":5,"offset":10394},"end":{"line":236,"column":100,"offset":10489},"indent":[]}}],"position":{"start":{"line":236,"column":1,"offset":10390},"end":{"line":236,"column":100,"offset":10489},"indent":[]}},{"type":"code","lang":"js","meta":null,"value":"//Write a Java program to illustrate finally block with return statement in try block.\n public class FunyCodeException {\n    int show() {\n      try {\n        return 100;\n       }\n    finally {\n        System.out.println(\"I am from finally block\");\n       }\n    }\n    public static void main(String[] args) {\n        FunyCodeException codeException=new FunyCodeException();\n        System.out.println(codeException.show());\n       }\n    }","position":{"start":{"line":237,"column":1,"offset":10491},"end":{"line":253,"column":4,"offset":10954},"indent":[1,1,1,1,1,1,1,1,1,1,1,1,1,1,1,1]}},{"type":"code","lang":null,"meta":null,"value":"Output:\nI am from finally block\n100","position":{"start":{"line":254,"column":1,"offset":10956},"end":{"line":258,"column":4,"offset":11003},"indent":[1,1,1,1]}},{"type":"heading","depth":3,"children":[{"type":"text","value":"Example-7: Write a Java program to illustrate the working of finally block when an exception occurs in try block but is not handled in the catch block.","position":{"start":{"line":259,"column":5,"offset":11009},"end":{"line":259,"column":156,"offset":11160},"indent":[]}}],"position":{"start":{"line":259,"column":1,"offset":11005},"end":{"line":259,"column":156,"offset":11160},"indent":[]}},{"type":"code","lang":"js","meta":null,"value":"// Write a Java program to illustrate the working of finally block when an exception occurs in try block but is not handled in the catch block.\n  public class FunyCodeException {\n    public static void main(String[] args) {\n      try {\n        String s=null;\n        System.out.println(s.length());\n       }\n    catch(ArithmeticException e) {\n        System.out.println(\"Here Arithmetic Exception\");\n    }\n    finally {\n        System.out.println(\"I am from finally block\");\n    }\n        System.out.println(\"Rest of the code\");\n    }\n   }","position":{"start":{"line":260,"column":1,"offset":11162},"end":{"line":277,"column":4,"offset":11728},"indent":[1,1,1,1,1,1,1,1,1,1,1,1,1,1,1,1,1]}},{"type":"code","lang":null,"meta":null,"value":"Output:\nI am from finally block\nException in thread \"main\" java.lang.NullPointerException: Cannot invoke \"String.length()\" because \"s\" is null at FunyCodeException.main(FunyCodeException.java:6)","position":{"start":{"line":278,"column":1,"offset":11730},"end":{"line":282,"column":4,"offset":11936},"indent":[1,1,1,1]}},{"type":"heading","depth":2,"children":[{"type":"text","value":"Nested Try-catch","position":{"start":{"line":283,"column":4,"offset":11941},"end":{"line":283,"column":20,"offset":11957},"indent":[]}}],"position":{"start":{"line":283,"column":1,"offset":11938},"end":{"line":283,"column":20,"offset":11957},"indent":[]}},{"type":"list","ordered":false,"start":null,"spread":false,"children":[{"type":"listItem","spread":false,"checked":null,"children":[{"type":"paragraph","children":[{"type":"text","value":"When a try catch block is present in another try block then it is called the nested try catch block.","position":{"start":{"line":284,"column":3,"offset":11961},"end":{"line":284,"column":103,"offset":12061},"indent":[]}}],"position":{"start":{"line":284,"column":3,"offset":11961},"end":{"line":284,"column":103,"offset":12061},"indent":[]}}],"position":{"start":{"line":284,"column":1,"offset":11959},"end":{"line":284,"column":103,"offset":12061},"indent":[]}},{"type":"listItem","spread":false,"checked":null,"children":[{"type":"paragraph","children":[{"type":"text","value":"Each time a try block does not have a catch handler for a particular exception, then the catch blocks of parent try block are inspected for that exception, if match is found that that catch block executes.","position":{"start":{"line":285,"column":3,"offset":12065},"end":{"line":285,"column":208,"offset":12270},"indent":[]}}],"position":{"start":{"line":285,"column":3,"offset":12065},"end":{"line":285,"column":208,"offset":12270},"indent":[]}}],"position":{"start":{"line":285,"column":1,"offset":12063},"end":{"line":285,"column":208,"offset":12270},"indent":[]}},{"type":"listItem","spread":false,"checked":null,"children":[{"type":"paragraph","children":[{"type":"text","value":"If neither catch block nor parent catch block handles exception then the system generated message would be shown for the exception, similar to what we see when we don’t handle exception.","position":{"start":{"line":286,"column":3,"offset":12274},"end":{"line":286,"column":189,"offset":12460},"indent":[]}}],"position":{"start":{"line":286,"column":3,"offset":12274},"end":{"line":286,"column":189,"offset":12460},"indent":[]}}],"position":{"start":{"line":286,"column":1,"offset":12272},"end":{"line":286,"column":189,"offset":12460},"indent":[]}},{"type":"listItem","spread":false,"checked":null,"children":[{"type":"paragraph","children":[{"type":"text","value":"The syntax of nested try catch block is","position":{"start":{"line":287,"column":3,"offset":12464},"end":{"line":287,"column":42,"offset":12503},"indent":[]}}],"position":{"start":{"line":287,"column":3,"offset":12464},"end":{"line":287,"column":42,"offset":12503},"indent":[]}}],"position":{"start":{"line":287,"column":1,"offset":12462},"end":{"line":287,"column":42,"offset":12503},"indent":[]}}],"position":{"start":{"line":284,"column":1,"offset":11959},"end":{"line":287,"column":42,"offset":12503},"indent":[1,1,1]}},{"type":"code","lang":"JS","meta":null,"value":"//Main try block\ntry {\n    try block-1;\n    //try-catch block inside another try block\n    try {\n         try block-2;\n          //try-catch block inside nested try block\n            try {\n         try block-3;\n            }\n    catch(Exception e2) {\n    //handle try block-3;\n       }\n    }\n    catch(Exception e1) {\n    //handle try block-2;\n    }\n    }\n    //Catch of Main(parent) try block\n    catch(Exception e3) {\n    ////handle try block-1;\n    }","position":{"start":{"line":288,"column":1,"offset":12505},"end":{"line":311,"column":4,"offset":12991},"indent":[1,1,1,1,1,1,1,1,1,1,1,1,1,1,1,1,1,1,1,1,1,1,1]}},{"type":"heading","depth":3,"children":[{"type":"text","value":"Example-8: Write a java program to illustrate nested try block with exception.","position":{"start":{"line":312,"column":5,"offset":12997},"end":{"line":312,"column":83,"offset":13075},"indent":[]}}],"position":{"start":{"line":312,"column":1,"offset":12993},"end":{"line":312,"column":83,"offset":13075},"indent":[]}},{"type":"code","lang":"js","meta":null,"value":"//Write a java program to illustrate nested try block with exception.\n  public class FunyCodeException {\n    public static void main(String[] args) {\n      try {\n          //try block-1\n           try {\n                //try block-2\n                 try {\n                     //try block-3\n                    String s=null;\n                    System.out.println(s.length());\n                   }\n                catch(ArithmeticException e) {\n                    System.out.println(\"Here Arithmetic Exception\");\n                    System.out.println(\"Here try block-3 handled\");\n                }\n             }\n       catch(ArrayIndexOutOfBoundsException e) {\n        System.out.println(\"Here Array Index Out Of Bounds Exception\");\n        System.out.println(\"Here try block-2 handled\");\n        }\n      }\n    catch(NumberFormatException e) {\n        System.out.println(\"Here Number Format Exception\");\n        System.out.println(\"Here try block-1 handled\");\n      }\n    catch(NullPointerException e) {\n        System.out.println(\"Here Null Pointer Exception\");\n    }\n    catch(Exception e) {\n        System.out.println(\"Other Exception\");\n      }\n    }\n  }","position":{"start":{"line":313,"column":1,"offset":13077},"end":{"line":348,"column":4,"offset":14284},"indent":[1,1,1,1,1,1,1,1,1,1,1,1,1,1,1,1,1,1,1,1,1,1,1,1,1,1,1,1,1,1,1,1,1,1,1]}},{"type":"code","lang":null,"meta":null,"value":"Output:\nHere Null Pointer Exception","position":{"start":{"line":349,"column":1,"offset":14286},"end":{"line":352,"column":4,"offset":14332},"indent":[1,1,1]}},{"type":"export","value":"export const _frontmatter = {\"title\":\"Try-catch Statement in Java\",\"category\":\"Java\",\"author\":\"Anonymous\",\"tags\":[\"#java\",\"#tutorial\"],\"date\":\"2021-01-03T00:00:00.000Z\",\"thumbnailText\":\"Java Tutorial-29\"}","position":{"start":{"line":354,"column":1,"offset":14334},"end":{"line":354,"column":205,"offset":14538},"indent":[]}}],"position":{"start":{"line":1,"column":1,"offset":0},"end":{"line":354,"column":205,"offset":14538}}},"scopeImports":["import * as React from 'react'"],"scopeIdentifiers":["React"],"body":"var _excluded = [\"components\"];\n\nfunction _extends() { _extends = Object.assign || function (target) { for (var i = 1; i < arguments.length; i++) { var source = arguments[i]; for (var key in source) { if (Object.prototype.hasOwnProperty.call(source, key)) { target[key] = source[key]; } } } return target; }; return _extends.apply(this, arguments); }\n\nfunction _objectWithoutProperties(source, excluded) { if (source == null) return {}; var target = _objectWithoutPropertiesLoose(source, excluded); var key, i; if (Object.getOwnPropertySymbols) { var sourceSymbolKeys = Object.getOwnPropertySymbols(source); for (i = 0; i < sourceSymbolKeys.length; i++) { key = sourceSymbolKeys[i]; if (excluded.indexOf(key) >= 0) continue; if (!Object.prototype.propertyIsEnumerable.call(source, key)) continue; target[key] = source[key]; } } return target; }\n\nfunction _objectWithoutPropertiesLoose(source, excluded) { if (source == null) return {}; var target = {}; var sourceKeys = Object.keys(source); var key, i; for (i = 0; i < sourceKeys.length; i++) { key = sourceKeys[i]; if (excluded.indexOf(key) >= 0) continue; target[key] = source[key]; } return target; }\n\n/* @jsxRuntime classic */\n\n/* @jsx mdx */\nvar _frontmatter = {\n  \"title\": \"Try-catch Statement in Java\",\n  \"category\": \"Java\",\n  \"author\": \"Anonymous\",\n  \"tags\": [\"#java\", \"#tutorial\"],\n  \"date\": \"2021-01-03T00:00:00.000Z\",\n  \"thumbnailText\": \"Java Tutorial-29\"\n};\nvar layoutProps = {\n  _frontmatter: _frontmatter\n};\nvar MDXLayout = \"wrapper\";\nreturn function MDXContent(_ref) {\n  var components = _ref.components,\n      props = _objectWithoutProperties(_ref, _excluded);\n\n  return mdx(MDXLayout, _extends({}, layoutProps, props, {\n    components: components,\n    mdxType: \"MDXLayout\"\n  }), mdx(\"h1\", {\n    \"id\": \"try-catch-statement-in-java\"\n  }, \"Try-catch Statement in Java\"), mdx(\"p\", null, \"The purpose of exception handling mechanism is to provide a means to detect and report an \\u201Cexceptional circumstance\\u201D so that appropriate action can be taken. The mechanism suggests incorporation of a separate error handling code that performs the following tasks:\"), mdx(\"ol\", null, mdx(\"li\", {\n    parentName: \"ol\"\n  }, \"Find the problem (Hit the exception).\"), mdx(\"li\", {\n    parentName: \"ol\"\n  }, \"Inform that an error has occurred (Throw the exception)\"), mdx(\"li\", {\n    parentName: \"ol\"\n  }, \"Receive the error information (Catch the exception)\"), mdx(\"li\", {\n    parentName: \"ol\"\n  }, \"Take corrective actions (Handle the exception)\\nThe error handling code basically consists of two segments, one to detect errors and to throw exceptions and the other to catch exceptions and to take appropriate actions.\\n\", mdx(\"figure\", {\n    parentName: \"li\",\n    \"className\": \"gatsby-resp-image-figure\",\n    \"style\": {}\n  }, \"\\n    \", mdx(\"span\", {\n    parentName: \"figure\",\n    \"className\": \"gatsby-resp-image-wrapper\",\n    \"style\": {\n      \"position\": \"relative\",\n      \"display\": \"block\",\n      \"marginLeft\": \"auto\",\n      \"marginRight\": \"auto\",\n      \"maxWidth\": \"784px\"\n    }\n  }, \"\\n      \", mdx(\"span\", {\n    parentName: \"span\",\n    \"className\": \"gatsby-resp-image-background-image\",\n    \"style\": {\n      \"paddingBottom\": \"62.456140350877185%\",\n      \"position\": \"relative\",\n      \"bottom\": \"0\",\n      \"left\": \"0\",\n      \"backgroundImage\": \"url('data:image/png;base64,iVBORw0KGgoAAAANSUhEUgAAABQAAAAMCAYAAABiDJ37AAAACXBIWXMAABJ0AAASdAHeZh94AAABcklEQVQoz42TWY/CMAyE+/9/FM+8lENUnBWIct/lKDcM+qxNt5vVSmvJSuqk4xnbCfRl7/f7xzqbzbTb7XS73bRer9VoNNRut7XZbHQ8HrXdbrVareRbAEARzO3H47H91Ol0VKvVzJvNptI0tThJJpOJsiyzxCRizQGLoKfTyRhig8FAURSp3++r1WrlcWw4HKpcLluixWKh+XyuwKcMg+v1aoewwJHGulwuLe7kEjufz3o8Ht+SYdPtdu0ihzjGpcvlYuDOqSfOnrPX66ViD/Bgv9+rVCoZbTIX5f/H/HIFMAEIo8BkxsjuGMLq+Xwa6/v9nsf9yTDAYiZAYAwwHaSefFMrmkKDptOpDoeDkeDcJXegv7qMAUJn3cwByNjU63X1ej0DdF315Qc+ZbcHDJkMc6VSsTVJEpOMXOTDOAxDVatVi+UMi2Dum+xI4ScaFsexyWbQUcC90WiUT0jO8K+XQo24yLzhzCAynVNjyuE/3Q9xypmgkJWlWAAAAABJRU5ErkJggg==')\",\n      \"backgroundSize\": \"cover\",\n      \"display\": \"block\"\n    }\n  }), \"\\n  \", mdx(\"img\", {\n    parentName: \"span\",\n    \"className\": \"gatsby-resp-image-image\",\n    \"alt\": \"Fig: try-catch block in Java \",\n    \"title\": \"Fig: try-catch block in Java \",\n    \"src\": \"/funycode/static/da399537f512cff6e8d6f4403402e950/ee623/trycatch.png\",\n    \"srcSet\": [\"/funycode/static/da399537f512cff6e8d6f4403402e950/050f2/trycatch.png 285w\", \"/funycode/static/da399537f512cff6e8d6f4403402e950/2b0be/trycatch.png 570w\", \"/funycode/static/da399537f512cff6e8d6f4403402e950/ee623/trycatch.png 784w\"],\n    \"sizes\": \"(max-width: 784px) 100vw, 784px\",\n    \"style\": {\n      \"width\": \"100%\",\n      \"height\": \"100%\",\n      \"margin\": \"0\",\n      \"verticalAlign\": \"middle\",\n      \"position\": \"absolute\",\n      \"top\": \"0\",\n      \"left\": \"0\"\n    },\n    \"loading\": \"lazy\",\n    \"decoding\": \"async\"\n  }), \"\\n    \"), \"\\n    \", mdx(\"figcaption\", {\n    parentName: \"figure\",\n    \"className\": \"gatsby-resp-image-figcaption\"\n  }, \"Fig: try-catch block in Java \"), \"\\n  \"))), mdx(\"ul\", null, mdx(\"li\", {\n    parentName: \"ul\"\n  }, \"Java exception handling is managed via five keywords: try, catch, throw, throws, finally.\"), mdx(\"li\", {\n    parentName: \"ul\"\n  }, \"Program statements that you want to monitor for exceptions are contained within a try block.\"), mdx(\"li\", {\n    parentName: \"ul\"\n  }, \"If an exception occurs within the try block, it is thrown. Your code can catch this exception (using catch) and then throw it in some rational manner.\"), mdx(\"li\", {\n    parentName: \"ul\"\n  }, \"System-generated exceptions are automatically thrown by Java run-time system.\"), mdx(\"li\", {\n    parentName: \"ul\"\n  }, \"To manually throw an exception, use the keyword throw; Any exception that is thrown out of a method must be specified as such by a throws clause.\"), mdx(\"li\", {\n    parentName: \"ul\"\n  }, \"Any code that absolutely must be executed before a method returns is put in finally block.\")), mdx(\"h2\", {\n    \"id\": \"java-exception-keywords\"\n  }, \"Java Exception Keywords\"), mdx(\"h3\", {\n    \"id\": \"try\"\n  }, \"try\"), mdx(\"ul\", null, mdx(\"li\", {\n    parentName: \"ul\"\n  }, \"The try block contains set of statements where an exception can occur.\"), mdx(\"li\", {\n    parentName: \"ul\"\n  }, \"A try block is always followed by a catch block, which handles the exception that occurs in associated try block.\"), mdx(\"li\", {\n    parentName: \"ul\"\n  }, \"A try block must be followed by catch blocks or finally block or both.\")), mdx(\"h3\", {\n    \"id\": \"catch\"\n  }, \"catch\"), mdx(\"ul\", null, mdx(\"li\", {\n    parentName: \"ul\"\n  }, \"A catch block is where you handle the exceptions, this block must follow the try block.\"), mdx(\"li\", {\n    parentName: \"ul\"\n  }, \"A single try block can have several catch blocks associated with it.\"), mdx(\"li\", {\n    parentName: \"ul\"\n  }, \"You can catch different exceptions in different catch blocks.\"), mdx(\"li\", {\n    parentName: \"ul\"\n  }, \"When an exception occurs in try block, the corresponding catch block that handles that particular exception executes.\"), mdx(\"li\", {\n    parentName: \"ul\"\n  }, \"For example if an arithmetic exception occurs in try block then the statements enclosed in catch block for arithmetic exception executes.\")), mdx(\"h3\", {\n    \"id\": \"finally\"\n  }, \"finally\"), mdx(\"ul\", null, mdx(\"li\", {\n    parentName: \"ul\"\n  }, \"A finally block contains all the crucial statements that must be executed whether exception occurs or not.\"), mdx(\"li\", {\n    parentName: \"ul\"\n  }, \"The statements present in this block will always execute regardless of whether exception occurs in try block or not such as closing a connection, stream etc.\")), mdx(\"h3\", {\n    \"id\": \"throw\"\n  }, \"throw\"), mdx(\"ul\", null, mdx(\"li\", {\n    parentName: \"ul\"\n  }, \"The \\u201Cthrow\\u201D keyword is used to throw an exception.\"), mdx(\"li\", {\n    parentName: \"ul\"\n  }, \"We can define our own set of conditions or rules and throw an exception explicitly using throw keyword.\"), mdx(\"li\", {\n    parentName: \"ul\"\n  }, \"For example, we can throw ArithmeticException when we divide number by 5, or any other numbers, what we need to do is just set the condition and throw any exception using throw keyword.\"), mdx(\"li\", {\n    parentName: \"ul\"\n  }, \"Throw keyword can also be used for throwing custom exceptions,\")), mdx(\"h3\", {\n    \"id\": \"throws\"\n  }, \"Throws\"), mdx(\"ul\", null, mdx(\"li\", {\n    parentName: \"ul\"\n  }, \"The \\u201Cthrows\\u201D keyword is used to declare exceptions.\"), mdx(\"li\", {\n    parentName: \"ul\"\n  }, \"It doesn\\u2019t throw an exception.\"), mdx(\"li\", {\n    parentName: \"ul\"\n  }, \"It specifies that there may occur an exception in the method.\"), mdx(\"li\", {\n    parentName: \"ul\"\n  }, \"It is always used with method signature.\"), mdx(\"li\", {\n    parentName: \"ul\"\n  }, \"This is the general form of an exception-handling block\")), mdx(\"pre\", null, mdx(\"code\", {\n    parentName: \"pre\",\n    \"className\": \"language-js\"\n  }, \"try\\n    {\\n    // block of code to monitor for errors\\n    }\\ncatch (ExceptionTypel exOb)\\n    {\\n    // exception handler for ExceptionTypel\\n    }catch (ExceptionType2 exOb)\\n    {\\n    // exception handler for ExceptionType2\\n    }\\n// . . . . . . . . .\\nfinally\\n    {\\n    // block of code to be executed before try block ends\\n    }\\n\")), mdx(\"h2\", {\n    \"id\": \"common-scenarios-of-java-exceptions\"\n  }, \"Common Scenarios of Java Exceptions\"), mdx(\"h2\", {\n    \"id\": \"arithmeticexception\"\n  }, \"ArithmeticException\"), mdx(\"pre\", null, mdx(\"code\", {\n    parentName: \"pre\"\n  }, \"int a=50/0;//ArithmeticException\\n\")), mdx(\"h2\", {\n    \"id\": \"nullpointerexception\"\n  }, \"NullPointerException\"), mdx(\"pre\", null, mdx(\"code\", {\n    parentName: \"pre\"\n  }, \"String s=null;\\nSystem.out.println(s.length());//NullPointerException )\\n\")), mdx(\"h2\", {\n    \"id\": \"numberformatexception\"\n  }, \"NumberFormatException\"), mdx(\"pre\", null, mdx(\"code\", {\n    parentName: \"pre\"\n  }, \"String s=\\u201Dabc\\u201D;\\nint i=Integer.parseInt(s);//NumberFormatException\\n\")), mdx(\"h2\", {\n    \"id\": \"arrayindexoutofboundsexception\"\n  }, \"ArrayIndexOutOfBoundsException\"), mdx(\"pre\", null, mdx(\"code\", {\n    parentName: \"pre\"\n  }, \"int a[]=new int[5];\\na[10]=50; //ArrayIndexOutOfBoundsException\\n\")), mdx(\"h2\", {\n    \"id\": \"exception-handling-mechanism\"\n  }, \"Exception Handling Mechanism\"), mdx(\"ul\", null, mdx(\"li\", {\n    parentName: \"ul\"\n  }, mdx(\"p\", {\n    parentName: \"li\"\n  }, \"Default Exception Handling\")), mdx(\"li\", {\n    parentName: \"ul\"\n  }, mdx(\"p\", {\n    parentName: \"li\"\n  }, \"Customized Exception Handling\")), mdx(\"li\", {\n    parentName: \"ul\"\n  }, mdx(\"p\", {\n    parentName: \"li\"\n  }, \"Default Exception Handling\")), mdx(\"li\", {\n    parentName: \"ul\"\n  }, mdx(\"p\", {\n    parentName: \"li\"\n  }, \"Whenever inside a method, if an exception has occurred, the method creates an Object known as Exception Object and hands it off to the run-time system(JVM).\")), mdx(\"li\", {\n    parentName: \"ul\"\n  }, mdx(\"p\", {\n    parentName: \"li\"\n  }, \"The exception object contains name and description of the exception, and current state of the program where exception has occurred.\")), mdx(\"li\", {\n    parentName: \"ul\"\n  }, mdx(\"p\", {\n    parentName: \"li\"\n  }, \"Creating the Exception Object and handling it to the run-time system is called throwing an Exception.\")), mdx(\"li\", {\n    parentName: \"ul\"\n  }, mdx(\"p\", {\n    parentName: \"li\"\n  }, \"There might be the list of the methods that had been called to get to the method where exception was occurred.\")), mdx(\"li\", {\n    parentName: \"ul\"\n  }, mdx(\"p\", {\n    parentName: \"li\"\n  }, \"This ordered list of the methods is called Call Stack\"))), mdx(\"h3\", {\n    \"id\": \"example-1-write-a-java-program-to-illustrate-how-default-exception-is-thrown\"\n  }, \"Example-1: Write a java program to illustrate how default exception is thrown.\"), mdx(\"pre\", null, mdx(\"code\", {\n    parentName: \"pre\",\n    \"className\": \"language-js\"\n  }, \"//Write a java program to illustrate how default exception is thrown.\\npublic class FunyCodeException {\\n    public static void main(String[] args) {\\n    String s=null;\\n    System.out.println(s.length());\\n   }\\n }\\nOutput:\\nException in thread \\\"main\\\" java.lang.NullPointerException: Cannot invoke \\\"String.length()\\\" because \\\"s\\\" is null at FunyCodeException.main(FunyCodeException.java:6)\\n\")), mdx(\"h2\", {\n    \"id\": \"customized-exception-handling\"\n  }, \"Customized Exception Handling\"), mdx(\"ul\", null, mdx(\"li\", {\n    parentName: \"ul\"\n  }, \"Java exception handling is managed via five keywords: try, catch, throw, throws, and finally.\"), mdx(\"li\", {\n    parentName: \"ul\"\n  }, \"Program statements that you think can raise exceptions are contained within a try block. If an exception occurs within the try block, it is thrown.\"), mdx(\"li\", {\n    parentName: \"ul\"\n  }, \"Your code can catch this exception (using catch block) and handle it in some rational manner.\"), mdx(\"li\", {\n    parentName: \"ul\"\n  }, \"System-generated exceptions are automatically thrown by the Java run-time system.\"), mdx(\"li\", {\n    parentName: \"ul\"\n  }, \"To manually throw an exception, use the keyword throw.\"), mdx(\"li\", {\n    parentName: \"ul\"\n  }, \"Any exception that is thrown out of a method must be specified as such by a throws clause.\"), mdx(\"li\", {\n    parentName: \"ul\"\n  }, \"Any code that absolutely must be executed after a try block completes is put in a finally block.\")), mdx(\"h3\", {\n    \"id\": \"example-2-write-a-java-program-to-illustrate-simple-exception-using-try-catch-block\"\n  }, \"Example-2: Write a java program to illustrate simple exception using try catch block.\"), mdx(\"pre\", null, mdx(\"code\", {\n    parentName: \"pre\",\n    \"className\": \"language-js\"\n  }, \"//Write a java program to illustrate simple exception using try catch block.\\npublic class FunyCodeException {\\n    public static void main(String[] args) {\\n    try {\\n      int a=100,b=0;\\n      System.out.println(a/b);\\n    }\\n    catch(Exception e) {\\n      System.out.println(e);\\n    }\\n  System.out.println(\\\"Rest of the code\\\");\\n  }\\n }\\n\")), mdx(\"pre\", null, mdx(\"code\", {\n    parentName: \"pre\"\n  }, \"Output:\\njava.lang.ArithmeticException: / by zero\\nRest of the code\\n\")), mdx(\"h3\", {\n    \"id\": \"example-3-write-a-java-program-to-illustrate-null-pointer-exception-using-try-catch-block\"\n  }, \"Example-3: Write a java program to illustrate null pointer exception using try catch block.\"), mdx(\"pre\", null, mdx(\"code\", {\n    parentName: \"pre\",\n    \"className\": \"language-js\"\n  }, \"//Write a java program to illustrate null pointer exception using try catch block.\\npublic class FunyCodeException {\\n  public static void main(String[] args) {\\n    try {\\n      String s=null;\\n      System.out.println(s.length());\\n      }\\n    catch(NullPointerException e) {\\n      System.out.println(e);\\n     }\\n      System.out.println(\\\"Rest of the code\\\");\\n     }\\n   }\\n\")), mdx(\"pre\", null, mdx(\"code\", {\n    parentName: \"pre\"\n  }, \"Output:\\njava.lang.NullPointerException: Cannot invoke \\\"String.length()\\\" because \\\"s\\\" is null\\nRest of the code\\n\")), mdx(\"h2\", {\n    \"id\": \"multiple-catch-blocks-in-java\"\n  }, \"Multiple Catch Blocks in Java\"), mdx(\"ul\", null, mdx(\"li\", {\n    parentName: \"ul\"\n  }, \"A single try block can have any number of catch blocks.\"), mdx(\"li\", {\n    parentName: \"ul\"\n  }, \"A generic catch block can handle all the exceptions. Whether it is\"), mdx(\"li\", {\n    parentName: \"ul\"\n  }, \"ArrayIndexOutOfBoundsException or ArithmeticException or NullPointerException or any other type of exception\")), mdx(\"pre\", null, mdx(\"code\", {\n    parentName: \"pre\"\n  }, \"catch(Exception e){\\n//This catch block catches all the exceptions\\n}\\n\")), mdx(\"ul\", null, mdx(\"li\", {\n    parentName: \"ul\"\n  }, \"If no exception occurs in try block then the catch blocks are completely ignored.\"), mdx(\"li\", {\n    parentName: \"ul\"\n  }, \"Corresponding catch blocks execute for that specific type of exception:\"), mdx(\"li\", {\n    parentName: \"ul\"\n  }, \"catch(ArithmeticException e) is a catch block that can hanlde ArithmeticException\"), mdx(\"li\", {\n    parentName: \"ul\"\n  }, \"catch(NullPointerException e) is a catch block that can handle NullPointerException\")), mdx(\"h3\", {\n    \"id\": \"example-4-write-a-java-program-to-illustrate-multiple-catch-block-in-single-try-block\"\n  }, \"Example-4: Write a java program to illustrate multiple catch block in single try block.\"), mdx(\"pre\", null, mdx(\"code\", {\n    parentName: \"pre\",\n    \"className\": \"language-js\"\n  }, \"//Write a java program to illustrate multiple catch block in single try block.\\n  public class FunyCodeException {\\n    public static void main(String[] args) {\\n      try {\\n        String s=null;\\n        System.out.println(s.length());\\n       }\\n    catch(ArithmeticException e) {\\n        System.out.println(\\\"Here Arithmetic Exception\\\");\\n    }\\n    catch(ArrayIndexOutOfBoundsException e) {\\n        System.out.println(\\\"Here Array Index Out O fBounds Exception\\\");\\n    }\\n    catch(NumberFormatException e) {\\n        System.out.println(\\\"Here Number Format Exception\\\");\\n    }\\n    catch(NullPointerException e) {\\n        System.out.println(\\\"Here Null Pointer Exception\\\");\\n    }\\n    catch(Exception e) {\\n        System.out.println(\\\"Other Exception\\\");\\n    }\\n        System.out.println(\\\"Rest of the code\\\");\\n    }\\n  }\\n\")), mdx(\"pre\", null, mdx(\"code\", {\n    parentName: \"pre\"\n  }, \"Output:\\nHere Null Pointer Exception\\nRest of the code\\nFinally Block\\n\")), mdx(\"ul\", null, mdx(\"li\", {\n    parentName: \"ul\"\n  }, \"A finally block must be associated with a try block, you cannot use finally without a try block.\"), mdx(\"li\", {\n    parentName: \"ul\"\n  }, \"You should place those statements in this block that must be executed always.\"), mdx(\"li\", {\n    parentName: \"ul\"\n  }, \"Finally block is optional, a try-catch block is sufficient for exception handling, however if you place a finally block then it will always run after the execution of try block.\"), mdx(\"li\", {\n    parentName: \"ul\"\n  }, \"In normal case when there is no exception in try block then the finally block is executed after try block.\"), mdx(\"li\", {\n    parentName: \"ul\"\n  }, \"However if an exception occurs then the catch block is executed before finally block.\"), mdx(\"li\", {\n    parentName: \"ul\"\n  }, \"An exception in the finally block, behaves exactly like any other exception.\"), mdx(\"li\", {\n    parentName: \"ul\"\n  }, \"The statements present in the finally block execute even if the try block contains control transfer statements like return, break or continue.\"), mdx(\"li\", {\n    parentName: \"ul\"\n  }, \"A try-finally block is possible without catch block.\"), mdx(\"li\", {\n    parentName: \"ul\"\n  }, \"Which means a try block can be used with finally without having a catch block.\")), mdx(\"h3\", {\n    \"id\": \"example-5-write-a-java-program-to-illustrate-finally-block-with-try-catch-block\"\n  }, \"Example-5: Write a Java program to illustrate finally block with try catch block.\"), mdx(\"pre\", null, mdx(\"code\", {\n    parentName: \"pre\",\n    \"className\": \"language-js\"\n  }, \"//Write a Java program to illustrate finally block with try catch block.\\n  public class FunyCodeException {\\n    public static void main(String[] args) {\\n     try {\\n        String s=null;\\n        System.out.println(s.length());\\n    }\\n    catch(NullPointerException e) {\\n        System.out.println(\\\"Here NullPointer Exception\\\");\\n    }\\n    //this block will execute alaways either exception or not\\n    finally {\\n        System.out.println(\\\"I am from finally block\\\");\\n    }\\n        System.out.println(\\\"Rest of the code\\\");\\n    }\\n  }\\n\")), mdx(\"pre\", null, mdx(\"code\", {\n    parentName: \"pre\"\n  }, \"Output:\\nHere NullPointer Exception\\nI am from finally block\\nRest of the code\\n\")), mdx(\"h3\", {\n    \"id\": \"example-6-write-a-java-program-to-illustrate-finally-block-with-return-statement-in-try-block\"\n  }, \"Example-6: Write a Java program to illustrate finally block with return statement in try block.\"), mdx(\"pre\", null, mdx(\"code\", {\n    parentName: \"pre\",\n    \"className\": \"language-js\"\n  }, \"//Write a Java program to illustrate finally block with return statement in try block.\\n public class FunyCodeException {\\n    int show() {\\n      try {\\n        return 100;\\n       }\\n    finally {\\n        System.out.println(\\\"I am from finally block\\\");\\n       }\\n    }\\n    public static void main(String[] args) {\\n        FunyCodeException codeException=new FunyCodeException();\\n        System.out.println(codeException.show());\\n       }\\n    }\\n\")), mdx(\"pre\", null, mdx(\"code\", {\n    parentName: \"pre\"\n  }, \"Output:\\nI am from finally block\\n100\\n\")), mdx(\"h3\", {\n    \"id\": \"example-7-write-a-java-program-to-illustrate-the-working-of-finally-block-when-an-exception-occurs-in-try-block-but-is-not-handled-in-the-catch-block\"\n  }, \"Example-7: Write a Java program to illustrate the working of finally block when an exception occurs in try block but is not handled in the catch block.\"), mdx(\"pre\", null, mdx(\"code\", {\n    parentName: \"pre\",\n    \"className\": \"language-js\"\n  }, \"// Write a Java program to illustrate the working of finally block when an exception occurs in try block but is not handled in the catch block.\\n  public class FunyCodeException {\\n    public static void main(String[] args) {\\n      try {\\n        String s=null;\\n        System.out.println(s.length());\\n       }\\n    catch(ArithmeticException e) {\\n        System.out.println(\\\"Here Arithmetic Exception\\\");\\n    }\\n    finally {\\n        System.out.println(\\\"I am from finally block\\\");\\n    }\\n        System.out.println(\\\"Rest of the code\\\");\\n    }\\n   }\\n\")), mdx(\"pre\", null, mdx(\"code\", {\n    parentName: \"pre\"\n  }, \"Output:\\nI am from finally block\\nException in thread \\\"main\\\" java.lang.NullPointerException: Cannot invoke \\\"String.length()\\\" because \\\"s\\\" is null at FunyCodeException.main(FunyCodeException.java:6)\\n\")), mdx(\"h2\", {\n    \"id\": \"nested-try-catch\"\n  }, \"Nested Try-catch\"), mdx(\"ul\", null, mdx(\"li\", {\n    parentName: \"ul\"\n  }, \"When a try catch block is present in another try block then it is called the nested try catch block.\"), mdx(\"li\", {\n    parentName: \"ul\"\n  }, \"Each time a try block does not have a catch handler for a particular exception, then the catch blocks of parent try block are inspected for that exception, if match is found that that catch block executes.\"), mdx(\"li\", {\n    parentName: \"ul\"\n  }, \"If neither catch block nor parent catch block handles exception then the system generated message would be shown for the exception, similar to what we see when we don\\u2019t handle exception.\"), mdx(\"li\", {\n    parentName: \"ul\"\n  }, \"The syntax of nested try catch block is\")), mdx(\"pre\", null, mdx(\"code\", {\n    parentName: \"pre\",\n    \"className\": \"language-JS\"\n  }, \"//Main try block\\ntry {\\n    try block-1;\\n    //try-catch block inside another try block\\n    try {\\n         try block-2;\\n          //try-catch block inside nested try block\\n            try {\\n         try block-3;\\n            }\\n    catch(Exception e2) {\\n    //handle try block-3;\\n       }\\n    }\\n    catch(Exception e1) {\\n    //handle try block-2;\\n    }\\n    }\\n    //Catch of Main(parent) try block\\n    catch(Exception e3) {\\n    ////handle try block-1;\\n    }\\n\")), mdx(\"h3\", {\n    \"id\": \"example-8-write-a-java-program-to-illustrate-nested-try-block-with-exception\"\n  }, \"Example-8: Write a java program to illustrate nested try block with exception.\"), mdx(\"pre\", null, mdx(\"code\", {\n    parentName: \"pre\",\n    \"className\": \"language-js\"\n  }, \"//Write a java program to illustrate nested try block with exception.\\n  public class FunyCodeException {\\n    public static void main(String[] args) {\\n      try {\\n          //try block-1\\n           try {\\n                //try block-2\\n                 try {\\n                     //try block-3\\n                    String s=null;\\n                    System.out.println(s.length());\\n                   }\\n                catch(ArithmeticException e) {\\n                    System.out.println(\\\"Here Arithmetic Exception\\\");\\n                    System.out.println(\\\"Here try block-3 handled\\\");\\n                }\\n             }\\n       catch(ArrayIndexOutOfBoundsException e) {\\n        System.out.println(\\\"Here Array Index Out Of Bounds Exception\\\");\\n        System.out.println(\\\"Here try block-2 handled\\\");\\n        }\\n      }\\n    catch(NumberFormatException e) {\\n        System.out.println(\\\"Here Number Format Exception\\\");\\n        System.out.println(\\\"Here try block-1 handled\\\");\\n      }\\n    catch(NullPointerException e) {\\n        System.out.println(\\\"Here Null Pointer Exception\\\");\\n    }\\n    catch(Exception e) {\\n        System.out.println(\\\"Other Exception\\\");\\n      }\\n    }\\n  }\\n\")), mdx(\"pre\", null, mdx(\"code\", {\n    parentName: \"pre\"\n  }, \"Output:\\nHere Null Pointer Exception\\n\")));\n}\n;\nMDXContent.isMDXComponent = true;","rawMDXOutput":"/* @jsx mdx */\nimport { mdx } from '@mdx-js/react';\n/* @jsxRuntime classic */\n/* @jsx mdx */\n\nexport const _frontmatter = {\n  \"title\": \"Try-catch Statement in Java\",\n  \"category\": \"Java\",\n  \"author\": \"Anonymous\",\n  \"tags\": [\"#java\", \"#tutorial\"],\n  \"date\": \"2021-01-03T00:00:00.000Z\",\n  \"thumbnailText\": \"Java Tutorial-29\"\n};\n\nconst layoutProps = {\n  _frontmatter\n};\nconst MDXLayout = \"wrapper\"\nexport default function MDXContent({\n  components,\n  ...props\n}) {\n  return <MDXLayout {...layoutProps} {...props} components={components} mdxType=\"MDXLayout\">\n    <h1 {...{\n      \"id\": \"try-catch-statement-in-java\"\n    }}>{`Try-catch Statement in Java`}</h1>\n    <p>{`The purpose of exception handling mechanism is to provide a means to detect and report an “exceptional circumstance” so that appropriate action can be taken. The mechanism suggests incorporation of a separate error handling code that performs the following tasks:`}</p>\n    <ol>\n      <li parentName=\"ol\">{`Find the problem (Hit the exception).`}</li>\n      <li parentName=\"ol\">{`Inform that an error has occurred (Throw the exception)`}</li>\n      <li parentName=\"ol\">{`Receive the error information (Catch the exception)`}</li>\n      <li parentName=\"ol\">{`Take corrective actions (Handle the exception)\nThe error handling code basically consists of two segments, one to detect errors and to throw exceptions and the other to catch exceptions and to take appropriate actions.\n`}<figure parentName=\"li\" {...{\n          \"className\": \"gatsby-resp-image-figure\",\n          \"style\": {}\n        }}>{`\n    `}<span parentName=\"figure\" {...{\n            \"className\": \"gatsby-resp-image-wrapper\",\n            \"style\": {\n              \"position\": \"relative\",\n              \"display\": \"block\",\n              \"marginLeft\": \"auto\",\n              \"marginRight\": \"auto\",\n              \"maxWidth\": \"784px\"\n            }\n          }}>{`\n      `}<span parentName=\"span\" {...{\n              \"className\": \"gatsby-resp-image-background-image\",\n              \"style\": {\n                \"paddingBottom\": \"62.456140350877185%\",\n                \"position\": \"relative\",\n                \"bottom\": \"0\",\n                \"left\": \"0\",\n                \"backgroundImage\": \"url('data:image/png;base64,iVBORw0KGgoAAAANSUhEUgAAABQAAAAMCAYAAABiDJ37AAAACXBIWXMAABJ0AAASdAHeZh94AAABcklEQVQoz42TWY/CMAyE+/9/FM+8lENUnBWIct/lKDcM+qxNt5vVSmvJSuqk4xnbCfRl7/f7xzqbzbTb7XS73bRer9VoNNRut7XZbHQ8HrXdbrVareRbAEARzO3H47H91Ol0VKvVzJvNptI0tThJJpOJsiyzxCRizQGLoKfTyRhig8FAURSp3++r1WrlcWw4HKpcLluixWKh+XyuwKcMg+v1aoewwJHGulwuLe7kEjufz3o8Ht+SYdPtdu0ihzjGpcvlYuDOqSfOnrPX66ViD/Bgv9+rVCoZbTIX5f/H/HIFMAEIo8BkxsjuGMLq+Xwa6/v9nsf9yTDAYiZAYAwwHaSefFMrmkKDptOpDoeDkeDcJXegv7qMAUJn3cwByNjU63X1ej0DdF315Qc+ZbcHDJkMc6VSsTVJEpOMXOTDOAxDVatVi+UMi2Dum+xI4ScaFsexyWbQUcC90WiUT0jO8K+XQo24yLzhzCAynVNjyuE/3Q9xypmgkJWlWAAAAABJRU5ErkJggg==')\",\n                \"backgroundSize\": \"cover\",\n                \"display\": \"block\"\n              }\n            }}></span>{`\n  `}<img parentName=\"span\" {...{\n              \"className\": \"gatsby-resp-image-image\",\n              \"alt\": \"Fig: try-catch block in Java \",\n              \"title\": \"Fig: try-catch block in Java \",\n              \"src\": \"/funycode/static/da399537f512cff6e8d6f4403402e950/ee623/trycatch.png\",\n              \"srcSet\": [\"/funycode/static/da399537f512cff6e8d6f4403402e950/050f2/trycatch.png 285w\", \"/funycode/static/da399537f512cff6e8d6f4403402e950/2b0be/trycatch.png 570w\", \"/funycode/static/da399537f512cff6e8d6f4403402e950/ee623/trycatch.png 784w\"],\n              \"sizes\": \"(max-width: 784px) 100vw, 784px\",\n              \"style\": {\n                \"width\": \"100%\",\n                \"height\": \"100%\",\n                \"margin\": \"0\",\n                \"verticalAlign\": \"middle\",\n                \"position\": \"absolute\",\n                \"top\": \"0\",\n                \"left\": \"0\"\n              },\n              \"loading\": \"lazy\",\n              \"decoding\": \"async\"\n            }}></img>{`\n    `}</span>{`\n    `}<figcaption parentName=\"figure\" {...{\n            \"className\": \"gatsby-resp-image-figcaption\"\n          }}>{`Fig: try-catch block in Java `}</figcaption>{`\n  `}</figure></li>\n    </ol>\n    <ul>\n      <li parentName=\"ul\">{`Java exception handling is managed via five keywords: try, catch, throw, throws, finally.`}</li>\n      <li parentName=\"ul\">{`Program statements that you want to monitor for exceptions are contained within a try block.`}</li>\n      <li parentName=\"ul\">{`If an exception occurs within the try block, it is thrown. Your code can catch this exception (using catch) and then throw it in some rational manner.`}</li>\n      <li parentName=\"ul\">{`System-generated exceptions are automatically thrown by Java run-time system.`}</li>\n      <li parentName=\"ul\">{`To manually throw an exception, use the keyword throw; Any exception that is thrown out of a method must be specified as such by a throws clause.`}</li>\n      <li parentName=\"ul\">{`Any code that absolutely must be executed before a method returns is put in finally block.`}</li>\n    </ul>\n    <h2 {...{\n      \"id\": \"java-exception-keywords\"\n    }}>{`Java Exception Keywords`}</h2>\n    <h3 {...{\n      \"id\": \"try\"\n    }}>{`try`}</h3>\n    <ul>\n      <li parentName=\"ul\">{`The try block contains set of statements where an exception can occur.`}</li>\n      <li parentName=\"ul\">{`A try block is always followed by a catch block, which handles the exception that occurs in associated try block.`}</li>\n      <li parentName=\"ul\">{`A try block must be followed by catch blocks or finally block or both.`}</li>\n    </ul>\n    <h3 {...{\n      \"id\": \"catch\"\n    }}>{`catch`}</h3>\n    <ul>\n      <li parentName=\"ul\">{`A catch block is where you handle the exceptions, this block must follow the try block.`}</li>\n      <li parentName=\"ul\">{`A single try block can have several catch blocks associated with it.`}</li>\n      <li parentName=\"ul\">{`You can catch different exceptions in different catch blocks.`}</li>\n      <li parentName=\"ul\">{`When an exception occurs in try block, the corresponding catch block that handles that particular exception executes.`}</li>\n      <li parentName=\"ul\">{`For example if an arithmetic exception occurs in try block then the statements enclosed in catch block for arithmetic exception executes.`}</li>\n    </ul>\n    <h3 {...{\n      \"id\": \"finally\"\n    }}>{`finally`}</h3>\n    <ul>\n      <li parentName=\"ul\">{`A finally block contains all the crucial statements that must be executed whether exception occurs or not.`}</li>\n      <li parentName=\"ul\">{`The statements present in this block will always execute regardless of whether exception occurs in try block or not such as closing a connection, stream etc.`}</li>\n    </ul>\n    <h3 {...{\n      \"id\": \"throw\"\n    }}>{`throw`}</h3>\n    <ul>\n      <li parentName=\"ul\">{`The “throw” keyword is used to throw an exception.`}</li>\n      <li parentName=\"ul\">{`We can define our own set of conditions or rules and throw an exception explicitly using throw keyword.`}</li>\n      <li parentName=\"ul\">{`For example, we can throw ArithmeticException when we divide number by 5, or any other numbers, what we need to do is just set the condition and throw any exception using throw keyword.`}</li>\n      <li parentName=\"ul\">{`Throw keyword can also be used for throwing custom exceptions,`}</li>\n    </ul>\n    <h3 {...{\n      \"id\": \"throws\"\n    }}>{`Throws`}</h3>\n    <ul>\n      <li parentName=\"ul\">{`The “throws” keyword is used to declare exceptions.`}</li>\n      <li parentName=\"ul\">{`It doesn’t throw an exception.`}</li>\n      <li parentName=\"ul\">{`It specifies that there may occur an exception in the method.`}</li>\n      <li parentName=\"ul\">{`It is always used with method signature.`}</li>\n      <li parentName=\"ul\">{`This is the general form of an exception-handling block`}</li>\n    </ul>\n    <pre><code parentName=\"pre\" {...{\n        \"className\": \"language-js\"\n      }}>{`try\n    {\n    // block of code to monitor for errors\n    }\ncatch (ExceptionTypel exOb)\n    {\n    // exception handler for ExceptionTypel\n    }catch (ExceptionType2 exOb)\n    {\n    // exception handler for ExceptionType2\n    }\n// . . . . . . . . .\nfinally\n    {\n    // block of code to be executed before try block ends\n    }\n`}</code></pre>\n    <h2 {...{\n      \"id\": \"common-scenarios-of-java-exceptions\"\n    }}>{`Common Scenarios of Java Exceptions`}</h2>\n    <h2 {...{\n      \"id\": \"arithmeticexception\"\n    }}>{`ArithmeticException`}</h2>\n    <pre><code parentName=\"pre\" {...{}}>{`int a=50/0;//ArithmeticException\n`}</code></pre>\n    <h2 {...{\n      \"id\": \"nullpointerexception\"\n    }}>{`NullPointerException`}</h2>\n    <pre><code parentName=\"pre\" {...{}}>{`String s=null;\nSystem.out.println(s.length());//NullPointerException )\n`}</code></pre>\n    <h2 {...{\n      \"id\": \"numberformatexception\"\n    }}>{`NumberFormatException`}</h2>\n    <pre><code parentName=\"pre\" {...{}}>{`String s=”abc”;\nint i=Integer.parseInt(s);//NumberFormatException\n`}</code></pre>\n    <h2 {...{\n      \"id\": \"arrayindexoutofboundsexception\"\n    }}>{`ArrayIndexOutOfBoundsException`}</h2>\n    <pre><code parentName=\"pre\" {...{}}>{`int a[]=new int[5];\na[10]=50; //ArrayIndexOutOfBoundsException\n`}</code></pre>\n    <h2 {...{\n      \"id\": \"exception-handling-mechanism\"\n    }}>{`Exception Handling Mechanism`}</h2>\n    <ul>\n      <li parentName=\"ul\">\n        <p parentName=\"li\">{`Default Exception Handling`}</p>\n      </li>\n      <li parentName=\"ul\">\n        <p parentName=\"li\">{`Customized Exception Handling`}</p>\n      </li>\n      <li parentName=\"ul\">\n        <p parentName=\"li\">{`Default Exception Handling`}</p>\n      </li>\n      <li parentName=\"ul\">\n        <p parentName=\"li\">{`Whenever inside a method, if an exception has occurred, the method creates an Object known as Exception Object and hands it off to the run-time system(JVM).`}</p>\n      </li>\n      <li parentName=\"ul\">\n        <p parentName=\"li\">{`The exception object contains name and description of the exception, and current state of the program where exception has occurred.`}</p>\n      </li>\n      <li parentName=\"ul\">\n        <p parentName=\"li\">{`Creating the Exception Object and handling it to the run-time system is called throwing an Exception.`}</p>\n      </li>\n      <li parentName=\"ul\">\n        <p parentName=\"li\">{`There might be the list of the methods that had been called to get to the method where exception was occurred.`}</p>\n      </li>\n      <li parentName=\"ul\">\n        <p parentName=\"li\">{`This ordered list of the methods is called Call Stack`}</p>\n      </li>\n    </ul>\n    <h3 {...{\n      \"id\": \"example-1-write-a-java-program-to-illustrate-how-default-exception-is-thrown\"\n    }}>{`Example-1: Write a java program to illustrate how default exception is thrown.`}</h3>\n    <pre><code parentName=\"pre\" {...{\n        \"className\": \"language-js\"\n      }}>{`//Write a java program to illustrate how default exception is thrown.\npublic class FunyCodeException {\n    public static void main(String[] args) {\n    String s=null;\n    System.out.println(s.length());\n   }\n }\nOutput:\nException in thread \"main\" java.lang.NullPointerException: Cannot invoke \"String.length()\" because \"s\" is null at FunyCodeException.main(FunyCodeException.java:6)\n`}</code></pre>\n    <h2 {...{\n      \"id\": \"customized-exception-handling\"\n    }}>{`Customized Exception Handling`}</h2>\n    <ul>\n      <li parentName=\"ul\">{`Java exception handling is managed via five keywords: try, catch, throw, throws, and finally.`}</li>\n      <li parentName=\"ul\">{`Program statements that you think can raise exceptions are contained within a try block. If an exception occurs within the try block, it is thrown.`}</li>\n      <li parentName=\"ul\">{`Your code can catch this exception (using catch block) and handle it in some rational manner.`}</li>\n      <li parentName=\"ul\">{`System-generated exceptions are automatically thrown by the Java run-time system.`}</li>\n      <li parentName=\"ul\">{`To manually throw an exception, use the keyword throw.`}</li>\n      <li parentName=\"ul\">{`Any exception that is thrown out of a method must be specified as such by a throws clause.`}</li>\n      <li parentName=\"ul\">{`Any code that absolutely must be executed after a try block completes is put in a finally block.`}</li>\n    </ul>\n    <h3 {...{\n      \"id\": \"example-2-write-a-java-program-to-illustrate-simple-exception-using-try-catch-block\"\n    }}>{`Example-2: Write a java program to illustrate simple exception using try catch block.`}</h3>\n    <pre><code parentName=\"pre\" {...{\n        \"className\": \"language-js\"\n      }}>{`//Write a java program to illustrate simple exception using try catch block.\npublic class FunyCodeException {\n    public static void main(String[] args) {\n    try {\n      int a=100,b=0;\n      System.out.println(a/b);\n    }\n    catch(Exception e) {\n      System.out.println(e);\n    }\n  System.out.println(\"Rest of the code\");\n  }\n }\n`}</code></pre>\n    <pre><code parentName=\"pre\" {...{}}>{`Output:\njava.lang.ArithmeticException: / by zero\nRest of the code\n`}</code></pre>\n    <h3 {...{\n      \"id\": \"example-3-write-a-java-program-to-illustrate-null-pointer-exception-using-try-catch-block\"\n    }}>{`Example-3: Write a java program to illustrate null pointer exception using try catch block.`}</h3>\n    <pre><code parentName=\"pre\" {...{\n        \"className\": \"language-js\"\n      }}>{`//Write a java program to illustrate null pointer exception using try catch block.\npublic class FunyCodeException {\n  public static void main(String[] args) {\n    try {\n      String s=null;\n      System.out.println(s.length());\n      }\n    catch(NullPointerException e) {\n      System.out.println(e);\n     }\n      System.out.println(\"Rest of the code\");\n     }\n   }\n`}</code></pre>\n    <pre><code parentName=\"pre\" {...{}}>{`Output:\njava.lang.NullPointerException: Cannot invoke \"String.length()\" because \"s\" is null\nRest of the code\n`}</code></pre>\n    <h2 {...{\n      \"id\": \"multiple-catch-blocks-in-java\"\n    }}>{`Multiple Catch Blocks in Java`}</h2>\n    <ul>\n      <li parentName=\"ul\">{`A single try block can have any number of catch blocks.`}</li>\n      <li parentName=\"ul\">{`A generic catch block can handle all the exceptions. Whether it is`}</li>\n      <li parentName=\"ul\">{`ArrayIndexOutOfBoundsException or ArithmeticException or NullPointerException or any other type of exception`}</li>\n    </ul>\n    <pre><code parentName=\"pre\" {...{}}>{`catch(Exception e){\n//This catch block catches all the exceptions\n}\n`}</code></pre>\n    <ul>\n      <li parentName=\"ul\">{`If no exception occurs in try block then the catch blocks are completely ignored.`}</li>\n      <li parentName=\"ul\">{`Corresponding catch blocks execute for that specific type of exception:`}</li>\n      <li parentName=\"ul\">{`catch(ArithmeticException e) is a catch block that can hanlde ArithmeticException`}</li>\n      <li parentName=\"ul\">{`catch(NullPointerException e) is a catch block that can handle NullPointerException`}</li>\n    </ul>\n    <h3 {...{\n      \"id\": \"example-4-write-a-java-program-to-illustrate-multiple-catch-block-in-single-try-block\"\n    }}>{`Example-4: Write a java program to illustrate multiple catch block in single try block.`}</h3>\n    <pre><code parentName=\"pre\" {...{\n        \"className\": \"language-js\"\n      }}>{`//Write a java program to illustrate multiple catch block in single try block.\n  public class FunyCodeException {\n    public static void main(String[] args) {\n      try {\n        String s=null;\n        System.out.println(s.length());\n       }\n    catch(ArithmeticException e) {\n        System.out.println(\"Here Arithmetic Exception\");\n    }\n    catch(ArrayIndexOutOfBoundsException e) {\n        System.out.println(\"Here Array Index Out O fBounds Exception\");\n    }\n    catch(NumberFormatException e) {\n        System.out.println(\"Here Number Format Exception\");\n    }\n    catch(NullPointerException e) {\n        System.out.println(\"Here Null Pointer Exception\");\n    }\n    catch(Exception e) {\n        System.out.println(\"Other Exception\");\n    }\n        System.out.println(\"Rest of the code\");\n    }\n  }\n`}</code></pre>\n    <pre><code parentName=\"pre\" {...{}}>{`Output:\nHere Null Pointer Exception\nRest of the code\nFinally Block\n`}</code></pre>\n    <ul>\n      <li parentName=\"ul\">{`A finally block must be associated with a try block, you cannot use finally without a try block.`}</li>\n      <li parentName=\"ul\">{`You should place those statements in this block that must be executed always.`}</li>\n      <li parentName=\"ul\">{`Finally block is optional, a try-catch block is sufficient for exception handling, however if you place a finally block then it will always run after the execution of try block.`}</li>\n      <li parentName=\"ul\">{`In normal case when there is no exception in try block then the finally block is executed after try block.`}</li>\n      <li parentName=\"ul\">{`However if an exception occurs then the catch block is executed before finally block.`}</li>\n      <li parentName=\"ul\">{`An exception in the finally block, behaves exactly like any other exception.`}</li>\n      <li parentName=\"ul\">{`The statements present in the finally block execute even if the try block contains control transfer statements like return, break or continue.`}</li>\n      <li parentName=\"ul\">{`A try-finally block is possible without catch block.`}</li>\n      <li parentName=\"ul\">{`Which means a try block can be used with finally without having a catch block.`}</li>\n    </ul>\n    <h3 {...{\n      \"id\": \"example-5-write-a-java-program-to-illustrate-finally-block-with-try-catch-block\"\n    }}>{`Example-5: Write a Java program to illustrate finally block with try catch block.`}</h3>\n    <pre><code parentName=\"pre\" {...{\n        \"className\": \"language-js\"\n      }}>{`//Write a Java program to illustrate finally block with try catch block.\n  public class FunyCodeException {\n    public static void main(String[] args) {\n     try {\n        String s=null;\n        System.out.println(s.length());\n    }\n    catch(NullPointerException e) {\n        System.out.println(\"Here NullPointer Exception\");\n    }\n    //this block will execute alaways either exception or not\n    finally {\n        System.out.println(\"I am from finally block\");\n    }\n        System.out.println(\"Rest of the code\");\n    }\n  }\n`}</code></pre>\n    <pre><code parentName=\"pre\" {...{}}>{`Output:\nHere NullPointer Exception\nI am from finally block\nRest of the code\n`}</code></pre>\n    <h3 {...{\n      \"id\": \"example-6-write-a-java-program-to-illustrate-finally-block-with-return-statement-in-try-block\"\n    }}>{`Example-6: Write a Java program to illustrate finally block with return statement in try block.`}</h3>\n    <pre><code parentName=\"pre\" {...{\n        \"className\": \"language-js\"\n      }}>{`//Write a Java program to illustrate finally block with return statement in try block.\n public class FunyCodeException {\n    int show() {\n      try {\n        return 100;\n       }\n    finally {\n        System.out.println(\"I am from finally block\");\n       }\n    }\n    public static void main(String[] args) {\n        FunyCodeException codeException=new FunyCodeException();\n        System.out.println(codeException.show());\n       }\n    }\n`}</code></pre>\n    <pre><code parentName=\"pre\" {...{}}>{`Output:\nI am from finally block\n100\n`}</code></pre>\n    <h3 {...{\n      \"id\": \"example-7-write-a-java-program-to-illustrate-the-working-of-finally-block-when-an-exception-occurs-in-try-block-but-is-not-handled-in-the-catch-block\"\n    }}>{`Example-7: Write a Java program to illustrate the working of finally block when an exception occurs in try block but is not handled in the catch block.`}</h3>\n    <pre><code parentName=\"pre\" {...{\n        \"className\": \"language-js\"\n      }}>{`// Write a Java program to illustrate the working of finally block when an exception occurs in try block but is not handled in the catch block.\n  public class FunyCodeException {\n    public static void main(String[] args) {\n      try {\n        String s=null;\n        System.out.println(s.length());\n       }\n    catch(ArithmeticException e) {\n        System.out.println(\"Here Arithmetic Exception\");\n    }\n    finally {\n        System.out.println(\"I am from finally block\");\n    }\n        System.out.println(\"Rest of the code\");\n    }\n   }\n`}</code></pre>\n    <pre><code parentName=\"pre\" {...{}}>{`Output:\nI am from finally block\nException in thread \"main\" java.lang.NullPointerException: Cannot invoke \"String.length()\" because \"s\" is null at FunyCodeException.main(FunyCodeException.java:6)\n`}</code></pre>\n    <h2 {...{\n      \"id\": \"nested-try-catch\"\n    }}>{`Nested Try-catch`}</h2>\n    <ul>\n      <li parentName=\"ul\">{`When a try catch block is present in another try block then it is called the nested try catch block.`}</li>\n      <li parentName=\"ul\">{`Each time a try block does not have a catch handler for a particular exception, then the catch blocks of parent try block are inspected for that exception, if match is found that that catch block executes.`}</li>\n      <li parentName=\"ul\">{`If neither catch block nor parent catch block handles exception then the system generated message would be shown for the exception, similar to what we see when we don’t handle exception.`}</li>\n      <li parentName=\"ul\">{`The syntax of nested try catch block is`}</li>\n    </ul>\n    <pre><code parentName=\"pre\" {...{\n        \"className\": \"language-JS\"\n      }}>{`//Main try block\ntry {\n    try block-1;\n    //try-catch block inside another try block\n    try {\n         try block-2;\n          //try-catch block inside nested try block\n            try {\n         try block-3;\n            }\n    catch(Exception e2) {\n    //handle try block-3;\n       }\n    }\n    catch(Exception e1) {\n    //handle try block-2;\n    }\n    }\n    //Catch of Main(parent) try block\n    catch(Exception e3) {\n    ////handle try block-1;\n    }\n`}</code></pre>\n    <h3 {...{\n      \"id\": \"example-8-write-a-java-program-to-illustrate-nested-try-block-with-exception\"\n    }}>{`Example-8: Write a java program to illustrate nested try block with exception.`}</h3>\n    <pre><code parentName=\"pre\" {...{\n        \"className\": \"language-js\"\n      }}>{`//Write a java program to illustrate nested try block with exception.\n  public class FunyCodeException {\n    public static void main(String[] args) {\n      try {\n          //try block-1\n           try {\n                //try block-2\n                 try {\n                     //try block-3\n                    String s=null;\n                    System.out.println(s.length());\n                   }\n                catch(ArithmeticException e) {\n                    System.out.println(\"Here Arithmetic Exception\");\n                    System.out.println(\"Here try block-3 handled\");\n                }\n             }\n       catch(ArrayIndexOutOfBoundsException e) {\n        System.out.println(\"Here Array Index Out Of Bounds Exception\");\n        System.out.println(\"Here try block-2 handled\");\n        }\n      }\n    catch(NumberFormatException e) {\n        System.out.println(\"Here Number Format Exception\");\n        System.out.println(\"Here try block-1 handled\");\n      }\n    catch(NullPointerException e) {\n        System.out.println(\"Here Null Pointer Exception\");\n    }\n    catch(Exception e) {\n        System.out.println(\"Other Exception\");\n      }\n    }\n  }\n`}</code></pre>\n    <pre><code parentName=\"pre\" {...{}}>{`Output:\nHere Null Pointer Exception\n`}</code></pre>\n\n    </MDXLayout>;\n}\n\n;\nMDXContent.isMDXComponent = true;"}}