{"expireTime":9007200883071766000,"key":"gatsby-plugin-mdx-entire-payload-de2e123dc5da256d1f82e41de572a040--undefined","val":{"mdast":{"type":"root","children":[{"type":"heading","depth":2,"children":[{"type":"text","value":"Exception Handling in C++","position":{"start":{"line":1,"column":4,"offset":3},"end":{"line":1,"column":29,"offset":28},"indent":[]}}],"position":{"start":{"line":1,"column":1,"offset":0},"end":{"line":1,"column":29,"offset":28},"indent":[]}},{"type":"paragraph","children":[{"type":"text","value":"In C++ errors can be divided into two categories compile time errors and run time errors. Compile time errors are syntactic errors which occurs during the writing of the program. Most common examples of compile time errors are missing semicolon, missing comma, missing double quotes, etc.","position":{"start":{"line":2,"column":1,"offset":30},"end":{"line":2,"column":289,"offset":318},"indent":[]}}],"position":{"start":{"line":2,"column":1,"offset":30},"end":{"line":2,"column":289,"offset":318},"indent":[]}},{"type":"list","ordered":false,"start":null,"spread":false,"children":[{"type":"listItem","spread":false,"checked":null,"children":[{"type":"paragraph","children":[{"type":"text","value":"They occurs mainly due to poor understanding of language or writing program without proper concentration to the program.","position":{"start":{"line":4,"column":3,"offset":324},"end":{"line":4,"column":123,"offset":444},"indent":[]}}],"position":{"start":{"line":4,"column":3,"offset":324},"end":{"line":4,"column":123,"offset":444},"indent":[]}}],"position":{"start":{"line":4,"column":1,"offset":322},"end":{"line":4,"column":123,"offset":444},"indent":[]}},{"type":"listItem","spread":false,"checked":null,"children":[{"type":"paragraph","children":[{"type":"text","value":"There are logical errors which are mainly due to improper understanding of the program logic by the programmer.","position":{"start":{"line":5,"column":3,"offset":448},"end":{"line":5,"column":114,"offset":559},"indent":[]}}],"position":{"start":{"line":5,"column":3,"offset":448},"end":{"line":5,"column":114,"offset":559},"indent":[]}}],"position":{"start":{"line":5,"column":1,"offset":446},"end":{"line":5,"column":114,"offset":559},"indent":[]}},{"type":"listItem","spread":false,"checked":null,"children":[{"type":"paragraph","children":[{"type":"text","value":"Logical errors cause the unexpected or unwanted output.","position":{"start":{"line":6,"column":3,"offset":563},"end":{"line":6,"column":58,"offset":618},"indent":[]}}],"position":{"start":{"line":6,"column":3,"offset":563},"end":{"line":6,"column":58,"offset":618},"indent":[]}}],"position":{"start":{"line":6,"column":1,"offset":561},"end":{"line":6,"column":58,"offset":618},"indent":[]}},{"type":"listItem","spread":false,"checked":null,"children":[{"type":"paragraph","children":[{"type":"text","value":"Exceptions are runtime errors which a programmer usually does not except.","position":{"start":{"line":7,"column":3,"offset":622},"end":{"line":7,"column":76,"offset":695},"indent":[]}}],"position":{"start":{"line":7,"column":3,"offset":622},"end":{"line":7,"column":76,"offset":695},"indent":[]}}],"position":{"start":{"line":7,"column":1,"offset":620},"end":{"line":7,"column":76,"offset":695},"indent":[]}},{"type":"listItem","spread":false,"checked":null,"children":[{"type":"paragraph","children":[{"type":"text","value":"They occurs accidentally which may result in abnormal termination of the program.","position":{"start":{"line":8,"column":3,"offset":699},"end":{"line":8,"column":84,"offset":780},"indent":[]}}],"position":{"start":{"line":8,"column":3,"offset":699},"end":{"line":8,"column":84,"offset":780},"indent":[]}}],"position":{"start":{"line":8,"column":1,"offset":697},"end":{"line":8,"column":84,"offset":780},"indent":[]}},{"type":"listItem","spread":false,"checked":null,"children":[{"type":"paragraph","children":[{"type":"text","value":"C++ provides exception handling mechanism which can be used to trap this exception and running programs smoothly after catching the exception.","position":{"start":{"line":9,"column":3,"offset":784},"end":{"line":9,"column":145,"offset":926},"indent":[]}}],"position":{"start":{"line":9,"column":3,"offset":784},"end":{"line":9,"column":145,"offset":926},"indent":[]}}],"position":{"start":{"line":9,"column":1,"offset":782},"end":{"line":9,"column":145,"offset":926},"indent":[]}},{"type":"listItem","spread":false,"checked":null,"children":[{"type":"paragraph","children":[{"type":"text","value":"Common examples of exceptions are division by zero, opening file which does not exist, insufficient memory, violating array bounds, etc.","position":{"start":{"line":10,"column":3,"offset":930},"end":{"line":10,"column":139,"offset":1066},"indent":[]}}],"position":{"start":{"line":10,"column":3,"offset":930},"end":{"line":10,"column":139,"offset":1066},"indent":[]}}],"position":{"start":{"line":10,"column":1,"offset":928},"end":{"line":10,"column":139,"offset":1066},"indent":[]}}],"position":{"start":{"line":4,"column":1,"offset":322},"end":{"line":10,"column":139,"offset":1066},"indent":[1,1,1,1,1,1]}},{"type":"heading","depth":2,"children":[{"type":"text","value":"Exception Handling","position":{"start":{"line":11,"column":4,"offset":1071},"end":{"line":11,"column":22,"offset":1089},"indent":[]}}],"position":{"start":{"line":11,"column":1,"offset":1068},"end":{"line":11,"column":22,"offset":1089},"indent":[]}},{"type":"list","ordered":false,"start":null,"spread":false,"children":[{"type":"listItem","spread":true,"checked":null,"children":[{"type":"paragraph","children":[{"type":"text","value":"Exception handling is the process to handle the exception if generated by the program at run time. The aim of exception handling is to write code which passes exception generated to a routine which can handle the exception and can take suitable action. Any exception handling mechanism must have the following steps:","position":{"start":{"line":12,"column":3,"offset":1093},"end":{"line":12,"column":319,"offset":1409},"indent":[]}}],"position":{"start":{"line":12,"column":3,"offset":1093},"end":{"line":12,"column":319,"offset":1409},"indent":[]}},{"type":"list","ordered":false,"start":null,"spread":false,"children":[{"type":"listItem","spread":false,"checked":null,"children":[{"type":"paragraph","children":[{"type":"text","value":"Step 1 : Writing exception class (optional).","position":{"start":{"line":14,"column":6,"offset":1418},"end":{"line":14,"column":50,"offset":1462},"indent":[]}}],"position":{"start":{"line":14,"column":6,"offset":1418},"end":{"line":14,"column":50,"offset":1462},"indent":[]}}],"position":{"start":{"line":14,"column":3,"offset":1415},"end":{"line":14,"column":50,"offset":1462},"indent":[]}},{"type":"listItem","spread":false,"checked":null,"children":[{"type":"paragraph","children":[{"type":"text","value":"Step 2 : Writing try block.","position":{"start":{"line":15,"column":6,"offset":1469},"end":{"line":15,"column":33,"offset":1496},"indent":[]}}],"position":{"start":{"line":15,"column":6,"offset":1469},"end":{"line":15,"column":33,"offset":1496},"indent":[]}}],"position":{"start":{"line":15,"column":3,"offset":1466},"end":{"line":15,"column":33,"offset":1496},"indent":[]}},{"type":"listItem","spread":false,"checked":null,"children":[{"type":"paragraph","children":[{"type":"text","value":"Step 3 : Throwing an exception.","position":{"start":{"line":16,"column":6,"offset":1503},"end":{"line":16,"column":37,"offset":1534},"indent":[]}}],"position":{"start":{"line":16,"column":6,"offset":1503},"end":{"line":16,"column":37,"offset":1534},"indent":[]}}],"position":{"start":{"line":16,"column":3,"offset":1500},"end":{"line":16,"column":37,"offset":1534},"indent":[]}},{"type":"listItem","spread":false,"checked":null,"children":[{"type":"paragraph","children":[{"type":"text","value":"Step 4 : Catching and handling the exception thrown.","position":{"start":{"line":17,"column":6,"offset":1541},"end":{"line":17,"column":58,"offset":1593},"indent":[]}}],"position":{"start":{"line":17,"column":6,"offset":1541},"end":{"line":17,"column":58,"offset":1593},"indent":[]}}],"position":{"start":{"line":17,"column":3,"offset":1538},"end":{"line":17,"column":58,"offset":1593},"indent":[]}}],"position":{"start":{"line":14,"column":3,"offset":1415},"end":{"line":17,"column":58,"offset":1593},"indent":[3,3,3]}}],"position":{"start":{"line":12,"column":1,"offset":1091},"end":{"line":17,"column":58,"offset":1593},"indent":[1,1,1,1,1]}}],"position":{"start":{"line":12,"column":1,"offset":1091},"end":{"line":17,"column":58,"offset":1593},"indent":[1,1,1,1,1]}},{"type":"heading","depth":2,"children":[{"type":"text","value":"Important Notes Regarding Exception Handling","position":{"start":{"line":19,"column":4,"offset":1600},"end":{"line":19,"column":48,"offset":1644},"indent":[]}}],"position":{"start":{"line":19,"column":1,"offset":1597},"end":{"line":19,"column":48,"offset":1644},"indent":[]}},{"type":"list","ordered":false,"start":null,"spread":false,"children":[{"type":"listItem","spread":false,"checked":null,"children":[{"type":"paragraph","children":[{"type":"text","value":"Exception is run-time error which may occur in the program","position":{"start":{"line":21,"column":3,"offset":1650},"end":{"line":21,"column":61,"offset":1708},"indent":[]}}],"position":{"start":{"line":21,"column":3,"offset":1650},"end":{"line":21,"column":61,"offset":1708},"indent":[]}}],"position":{"start":{"line":21,"column":1,"offset":1648},"end":{"line":21,"column":61,"offset":1708},"indent":[]}},{"type":"listItem","spread":false,"checked":null,"children":[{"type":"paragraph","children":[{"type":"text","value":"An exception if not handled may terminate the program abnormally.","position":{"start":{"line":22,"column":3,"offset":1712},"end":{"line":22,"column":68,"offset":1777},"indent":[]}}],"position":{"start":{"line":22,"column":3,"offset":1712},"end":{"line":22,"column":68,"offset":1777},"indent":[]}}],"position":{"start":{"line":22,"column":1,"offset":1710},"end":{"line":22,"column":68,"offset":1777},"indent":[]}},{"type":"listItem","spread":false,"checked":null,"children":[{"type":"paragraph","children":[{"type":"text","value":"To deal with exception, try-catch blocks are used.","position":{"start":{"line":23,"column":3,"offset":1781},"end":{"line":23,"column":53,"offset":1831},"indent":[]}}],"position":{"start":{"line":23,"column":3,"offset":1781},"end":{"line":23,"column":53,"offset":1831},"indent":[]}}],"position":{"start":{"line":23,"column":1,"offset":1779},"end":{"line":23,"column":53,"offset":1831},"indent":[]}},{"type":"listItem","spread":false,"checked":null,"children":[{"type":"paragraph","children":[{"type":"text","value":"An exception in programming term is considered an object which is thrown.","position":{"start":{"line":24,"column":3,"offset":1835},"end":{"line":24,"column":76,"offset":1908},"indent":[]}}],"position":{"start":{"line":24,"column":3,"offset":1835},"end":{"line":24,"column":76,"offset":1908},"indent":[]}}],"position":{"start":{"line":24,"column":1,"offset":1833},"end":{"line":24,"column":76,"offset":1908},"indent":[]}},{"type":"listItem","spread":false,"checked":null,"children":[{"type":"paragraph","children":[{"type":"text","value":"Any program code or function which may generate exception is placed in the try block. The exception is thrown by using keyword throw.","position":{"start":{"line":25,"column":3,"offset":1912},"end":{"line":25,"column":136,"offset":2045},"indent":[]}}],"position":{"start":{"line":25,"column":3,"offset":1912},"end":{"line":25,"column":136,"offset":2045},"indent":[]}}],"position":{"start":{"line":25,"column":1,"offset":1910},"end":{"line":25,"column":136,"offset":2045},"indent":[]}},{"type":"listItem","spread":false,"checked":null,"children":[{"type":"paragraph","children":[{"type":"text","value":"For one try block there may be multiple catch block.","position":{"start":{"line":26,"column":3,"offset":2049},"end":{"line":26,"column":55,"offset":2101},"indent":[]}}],"position":{"start":{"line":26,"column":3,"offset":2049},"end":{"line":26,"column":55,"offset":2101},"indent":[]}}],"position":{"start":{"line":26,"column":1,"offset":2047},"end":{"line":26,"column":55,"offset":2101},"indent":[]}},{"type":"listItem","spread":false,"checked":null,"children":[{"type":"paragraph","children":[{"type":"text","value":"An exception can be rethrown in case of nesting of try-catch blocks. To rethrown an exception, we simply write throw;","position":{"start":{"line":27,"column":3,"offset":2105},"end":{"line":27,"column":120,"offset":2222},"indent":[]}}],"position":{"start":{"line":27,"column":3,"offset":2105},"end":{"line":27,"column":120,"offset":2222},"indent":[]}}],"position":{"start":{"line":27,"column":1,"offset":2103},"end":{"line":27,"column":120,"offset":2222},"indent":[]}},{"type":"listItem","spread":false,"checked":null,"children":[{"type":"paragraph","children":[{"type":"text","value":"A function can specify what type of exception can be thrown by specifying in the function declaration.","position":{"start":{"line":28,"column":3,"offset":2226},"end":{"line":28,"column":105,"offset":2328},"indent":[]}}],"position":{"start":{"line":28,"column":3,"offset":2226},"end":{"line":28,"column":105,"offset":2328},"indent":[]}}],"position":{"start":{"line":28,"column":1,"offset":2224},"end":{"line":28,"column":105,"offset":2328},"indent":[]}},{"type":"listItem","spread":false,"checked":null,"children":[{"type":"paragraph","children":[{"type":"text","value":"Objects of user defined classes as exception can also be thrown.","position":{"start":{"line":29,"column":3,"offset":2332},"end":{"line":29,"column":67,"offset":2396},"indent":[]}}],"position":{"start":{"line":29,"column":3,"offset":2332},"end":{"line":29,"column":67,"offset":2396},"indent":[]}}],"position":{"start":{"line":29,"column":1,"offset":2330},"end":{"line":29,"column":67,"offset":2396},"indent":[]}},{"type":"listItem","spread":false,"checked":null,"children":[{"type":"paragraph","children":[{"type":"text","value":"The expression catch (…) can be used to catch all types of exceptions.","position":{"start":{"line":30,"column":3,"offset":2400},"end":{"line":30,"column":73,"offset":2470},"indent":[]}}],"position":{"start":{"line":30,"column":3,"offset":2400},"end":{"line":30,"column":73,"offset":2470},"indent":[]}}],"position":{"start":{"line":30,"column":1,"offset":2398},"end":{"line":30,"column":73,"offset":2470},"indent":[]}}],"position":{"start":{"line":21,"column":1,"offset":1648},"end":{"line":30,"column":73,"offset":2470},"indent":[1,1,1,1,1,1,1,1,1]}},{"type":"heading","depth":2,"children":[{"type":"text","value":"The try Block","position":{"start":{"line":31,"column":4,"offset":2475},"end":{"line":31,"column":17,"offset":2488},"indent":[]}}],"position":{"start":{"line":31,"column":1,"offset":2472},"end":{"line":31,"column":17,"offset":2488},"indent":[]}},{"type":"list","ordered":false,"start":null,"spread":true,"children":[{"type":"listItem","spread":false,"checked":null,"children":[{"type":"paragraph","children":[{"type":"text","value":"The exception is to be thrown to be written in the try block. Whenever an exception is generated in the try block, it is thrown.","position":{"start":{"line":32,"column":3,"offset":2492},"end":{"line":32,"column":131,"offset":2620},"indent":[]}}],"position":{"start":{"line":32,"column":3,"offset":2492},"end":{"line":32,"column":131,"offset":2620},"indent":[]}}],"position":{"start":{"line":32,"column":1,"offset":2490},"end":{"line":33,"column":1,"offset":2622},"indent":[1]}},{"type":"listItem","spread":false,"checked":null,"children":[{"type":"paragraph","children":[{"type":"text","value":"An exception is an object so we can say that an exception object is thrown.","position":{"start":{"line":34,"column":3,"offset":2626},"end":{"line":34,"column":78,"offset":2701},"indent":[]}}],"position":{"start":{"line":34,"column":3,"offset":2626},"end":{"line":34,"column":78,"offset":2701},"indent":[]}}],"position":{"start":{"line":34,"column":1,"offset":2624},"end":{"line":34,"column":78,"offset":2701},"indent":[]}},{"type":"listItem","spread":false,"checked":null,"children":[{"type":"paragraph","children":[{"type":"text","value":"The throw keyword is used for throwing an exception.","position":{"start":{"line":35,"column":3,"offset":2705},"end":{"line":35,"column":55,"offset":2757},"indent":[]}}],"position":{"start":{"line":35,"column":3,"offset":2705},"end":{"line":35,"column":55,"offset":2757},"indent":[]}}],"position":{"start":{"line":35,"column":1,"offset":2703},"end":{"line":35,"column":55,"offset":2757},"indent":[]}},{"type":"listItem","spread":false,"checked":null,"children":[{"type":"paragraph","children":[{"type":"text","value":"The usual practice of using the throw statement is as : throw exception;","position":{"start":{"line":36,"column":3,"offset":2761},"end":{"line":36,"column":75,"offset":2833},"indent":[]}}],"position":{"start":{"line":36,"column":3,"offset":2761},"end":{"line":36,"column":75,"offset":2833},"indent":[]}}],"position":{"start":{"line":36,"column":1,"offset":2759},"end":{"line":36,"column":75,"offset":2833},"indent":[]}},{"type":"listItem","spread":false,"checked":null,"children":[{"type":"paragraph","children":[{"type":"text","value":"For throwing an exception and simply throw; For re-throwing an exception.","position":{"start":{"line":37,"column":3,"offset":2837},"end":{"line":37,"column":76,"offset":2910},"indent":[]}}],"position":{"start":{"line":37,"column":3,"offset":2837},"end":{"line":37,"column":76,"offset":2910},"indent":[]}}],"position":{"start":{"line":37,"column":1,"offset":2835},"end":{"line":37,"column":76,"offset":2910},"indent":[]}}],"position":{"start":{"line":32,"column":1,"offset":2490},"end":{"line":37,"column":76,"offset":2910},"indent":[1,1,1,1,1]}},{"type":"code","lang":"js","meta":null,"value":"The syntax of try block is as shown :\ntry\n    {\n    statements;\n    statements;\n    statements;\n    throw exception;\n    }","position":{"start":{"line":38,"column":1,"offset":2912},"end":{"line":47,"column":4,"offset":3053},"indent":[1,1,1,1,1,1,1,1,1]}},{"type":"heading","depth":2,"children":[{"type":"text","value":"The catch Block","position":{"start":{"line":48,"column":4,"offset":3058},"end":{"line":48,"column":19,"offset":3073},"indent":[]}}],"position":{"start":{"line":48,"column":1,"offset":3055},"end":{"line":48,"column":19,"offset":3073},"indent":[]}},{"type":"list","ordered":false,"start":null,"spread":false,"children":[{"type":"listItem","spread":false,"checked":null,"children":[{"type":"paragraph","children":[{"type":"text","value":"An exception thrown by try block is caught by the catch block. A try block must have at least one catch, though there can be many catch block for catching different types of exceptions. A catch block must have a try block prior written which will throw an exception. The catch block is used as :","position":{"start":{"line":49,"column":3,"offset":3077},"end":{"line":49,"column":298,"offset":3372},"indent":[]}}],"position":{"start":{"line":49,"column":3,"offset":3077},"end":{"line":49,"column":298,"offset":3372},"indent":[]}}],"position":{"start":{"line":49,"column":1,"offset":3075},"end":{"line":49,"column":298,"offset":3372},"indent":[]}}],"position":{"start":{"line":49,"column":1,"offset":3075},"end":{"line":49,"column":298,"offset":3372},"indent":[]}},{"type":"code","lang":"js","meta":null,"value":"try\n    {\n    statements;\n    statements;\n    statements;\n    throw exception;\n    }\ncatch (object or argument)\n    {\n    statements for handling the exception;\n    }","position":{"start":{"line":50,"column":1,"offset":3374},"end":{"line":62,"column":4,"offset":3562},"indent":[1,1,1,1,1,1,1,1,1,1,1,1]}},{"type":"list","ordered":false,"start":null,"spread":false,"children":[{"type":"listItem","spread":false,"checked":null,"children":[{"type":"paragraph","children":[{"type":"text","value":"The catch block catches any exception thrown by the try block.","position":{"start":{"line":64,"column":3,"offset":3568},"end":{"line":64,"column":65,"offset":3630},"indent":[]}}],"position":{"start":{"line":64,"column":3,"offset":3568},"end":{"line":64,"column":65,"offset":3630},"indent":[]}}],"position":{"start":{"line":64,"column":1,"offset":3566},"end":{"line":64,"column":65,"offset":3630},"indent":[]}},{"type":"listItem","spread":false,"checked":null,"children":[{"type":"paragraph","children":[{"type":"text","value":"If exception thrown matches with the argument or object in the block, the statements written within the catch block and we say that exception thrown by try block was caught successfully by the catch block.","position":{"start":{"line":65,"column":3,"offset":3634},"end":{"line":65,"column":208,"offset":3839},"indent":[]}}],"position":{"start":{"line":65,"column":3,"offset":3634},"end":{"line":65,"column":208,"offset":3839},"indent":[]}}],"position":{"start":{"line":65,"column":1,"offset":3632},"end":{"line":65,"column":208,"offset":3839},"indent":[]}},{"type":"listItem","spread":false,"checked":null,"children":[{"type":"paragraph","children":[{"type":"text","value":"After the successful execution of the catch block statements any statements following the catch block will be executed.","position":{"start":{"line":66,"column":3,"offset":3843},"end":{"line":66,"column":122,"offset":3962},"indent":[]}}],"position":{"start":{"line":66,"column":3,"offset":3843},"end":{"line":66,"column":122,"offset":3962},"indent":[]}}],"position":{"start":{"line":66,"column":1,"offset":3841},"end":{"line":66,"column":122,"offset":3962},"indent":[]}},{"type":"listItem","spread":false,"checked":null,"children":[{"type":"paragraph","children":[{"type":"text","value":"If argument does not match with the exception thrown, catch couldn’t handle it and this may results in abnormal program termination.","position":{"start":{"line":67,"column":3,"offset":3966},"end":{"line":67,"column":135,"offset":4098},"indent":[]}}],"position":{"start":{"line":67,"column":3,"offset":3966},"end":{"line":67,"column":135,"offset":4098},"indent":[]}}],"position":{"start":{"line":67,"column":1,"offset":3964},"end":{"line":67,"column":135,"offset":4098},"indent":[]}}],"position":{"start":{"line":64,"column":1,"offset":3566},"end":{"line":67,"column":135,"offset":4098},"indent":[1,1,1]}},{"type":"heading","depth":2,"children":[{"type":"text","value":"Exception Handling Mechanism","position":{"start":{"line":68,"column":4,"offset":4103},"end":{"line":68,"column":32,"offset":4131},"indent":[]}}],"position":{"start":{"line":68,"column":1,"offset":4100},"end":{"line":68,"column":32,"offset":4131},"indent":[]}},{"type":"list","ordered":false,"start":null,"spread":true,"children":[{"type":"listItem","spread":false,"checked":null,"children":[{"type":"paragraph","children":[{"type":"text","value":"The try, throw and catch all together provide exception handling mechanism in C++.","position":{"start":{"line":69,"column":3,"offset":4135},"end":{"line":69,"column":85,"offset":4217},"indent":[]}}],"position":{"start":{"line":69,"column":3,"offset":4135},"end":{"line":69,"column":85,"offset":4217},"indent":[]}}],"position":{"start":{"line":69,"column":1,"offset":4133},"end":{"line":70,"column":1,"offset":4219},"indent":[1]}},{"type":"listItem","spread":false,"checked":null,"children":[{"type":"paragraph","children":[{"type":"text","value":"The exception is generated by the throw keyword which is written in the try block.","position":{"start":{"line":71,"column":3,"offset":4223},"end":{"line":71,"column":85,"offset":4305},"indent":[]}}],"position":{"start":{"line":71,"column":3,"offset":4223},"end":{"line":71,"column":85,"offset":4305},"indent":[]}}],"position":{"start":{"line":71,"column":1,"offset":4221},"end":{"line":71,"column":85,"offset":4305},"indent":[]}},{"type":"listItem","spread":false,"checked":null,"children":[{"type":"paragraph","children":[{"type":"text","value":"Any exception generated within this try block is thrown using this throw keyword. Immediately following the try block, catch block is written.","position":{"start":{"line":72,"column":3,"offset":4309},"end":{"line":72,"column":145,"offset":4451},"indent":[]}}],"position":{"start":{"line":72,"column":3,"offset":4309},"end":{"line":72,"column":145,"offset":4451},"indent":[]}}],"position":{"start":{"line":72,"column":1,"offset":4307},"end":{"line":72,"column":145,"offset":4451},"indent":[]}},{"type":"listItem","spread":false,"checked":null,"children":[{"type":"paragraph","children":[{"type":"text","value":"As soon as some run time errors occurs an exception is thrown by the try block using throw which informs the catch block that an error has occurred in the try block.","position":{"start":{"line":73,"column":3,"offset":4455},"end":{"line":73,"column":168,"offset":4620},"indent":[]}}],"position":{"start":{"line":73,"column":3,"offset":4455},"end":{"line":73,"column":168,"offset":4620},"indent":[]}}],"position":{"start":{"line":73,"column":1,"offset":4453},"end":{"line":73,"column":168,"offset":4620},"indent":[]}},{"type":"listItem","spread":false,"checked":null,"children":[{"type":"paragraph","children":[{"type":"text","value":"This try block is also known as exception generated block. The catch block is responsible for catching the execution thrown by the try block.","position":{"start":{"line":74,"column":3,"offset":4624},"end":{"line":74,"column":144,"offset":4765},"indent":[]}}],"position":{"start":{"line":74,"column":3,"offset":4624},"end":{"line":74,"column":144,"offset":4765},"indent":[]}}],"position":{"start":{"line":74,"column":1,"offset":4622},"end":{"line":74,"column":144,"offset":4765},"indent":[]}},{"type":"listItem","spread":false,"checked":null,"children":[{"type":"paragraph","children":[{"type":"text","value":"When try throw an exception, the control of the program passes to the catch block and if argument matches as explained earlier, exception is caught.","position":{"start":{"line":75,"column":3,"offset":4769},"end":{"line":75,"column":151,"offset":4917},"indent":[]}}],"position":{"start":{"line":75,"column":3,"offset":4769},"end":{"line":75,"column":151,"offset":4917},"indent":[]}}],"position":{"start":{"line":75,"column":1,"offset":4767},"end":{"line":75,"column":151,"offset":4917},"indent":[]}},{"type":"listItem","spread":false,"checked":null,"children":[{"type":"paragraph","children":[{"type":"text","value":"In case no exception is thrown the catch block is ignored and control passes to the next statement after the catch block.","position":{"start":{"line":76,"column":3,"offset":4921},"end":{"line":76,"column":124,"offset":5042},"indent":[]}}],"position":{"start":{"line":76,"column":3,"offset":4921},"end":{"line":76,"column":124,"offset":5042},"indent":[]}}],"position":{"start":{"line":76,"column":1,"offset":4919},"end":{"line":76,"column":124,"offset":5042},"indent":[]}}],"position":{"start":{"line":69,"column":1,"offset":4133},"end":{"line":76,"column":124,"offset":5042},"indent":[1,1,1,1,1,1,1]}},{"type":"heading","depth":3,"children":[{"type":"text","value":"Example-1: Write a C++ program to illustrate division by zero exception.","position":{"start":{"line":77,"column":5,"offset":5048},"end":{"line":77,"column":77,"offset":5120},"indent":[]}}],"position":{"start":{"line":77,"column":1,"offset":5044},"end":{"line":77,"column":77,"offset":5120},"indent":[]}},{"type":"code","lang":"js","meta":null,"value":"//Write a C++ program to illustrate division by zero exception.\n#include<iostream>\nusing namespace std;\nint main( )\n    {\n    float x,y;\n    cout<<\"Enter two numbers\\n\";\n    cin>>x>>y;\n    try\n        {\n        if(y!=0)\n        cout<<\"Div=\"<<x/y<<endl;\n        else\n        throw(y);\n        }\n    catch(float E)\n        {\n        cout<<\"Caught an Exception \\n\";\n        cout<<\"y=\"<<y<<endl;\n        }\n    cout<<\"Out of try catch block \\n\";\n    }","position":{"start":{"line":78,"column":1,"offset":5122},"end":{"line":101,"column":4,"offset":5601},"indent":[1,1,1,1,1,1,1,1,1,1,1,1,1,1,1,1,1,1,1,1,1,1,1]}},{"type":"code","lang":null,"meta":null,"value":"Output:\nEnter two numbers\n20\n0\nCaught an Exception\ny=0\nOut of try catch block","position":{"start":{"line":102,"column":1,"offset":5603},"end":{"line":110,"column":4,"offset":5696},"indent":[1,1,1,1,1,1,1,1]}},{"type":"heading","depth":3,"children":[{"type":"text","value":"Example-2: Write a C++ program to illustrate exception handling in subtraction of two number a and b where a>b.","position":{"start":{"line":111,"column":5,"offset":5702},"end":{"line":111,"column":116,"offset":5813},"indent":[]}}],"position":{"start":{"line":111,"column":1,"offset":5698},"end":{"line":111,"column":116,"offset":5813},"indent":[]}},{"type":"code","lang":"js","meta":null,"value":"// Write a C++ program to illustrate exception handling in subtraction of two number a and b where a>b.\n#include<iostream>\nusing namespace std;\nint main( )\n    {\n    int x,y;\n    bool m;\n    cout<<\"Enter two numbers \\n\";\n    cin>>x>>y;\n    m=x>y ?true :false;\n    try\n        {\n        if(m==true)\n        cout<<\"Subtraction=\"<<x-y<<endl;\n        else\n        throw(\"subtraction not possible\");\n        }\n    catch(const char* E)\n        {\n        cout<<\"Caught an Exception\\n\";\n        cout<<E<<endl;\n        }\n    cout<<\"Out of try catch block\\n\";\n    }","position":{"start":{"line":112,"column":1,"offset":5815},"end":{"line":137,"column":4,"offset":6405},"indent":[1,1,1,1,1,1,1,1,1,1,1,1,1,1,1,1,1,1,1,1,1,1,1,1,1]}},{"type":"code","lang":null,"meta":null,"value":"Output:\nEnter two numbers\n20\n30\nCaught an Exception\nsubtraction not possible\nOut of try catch block","position":{"start":{"line":138,"column":1,"offset":6407},"end":{"line":146,"column":4,"offset":6522},"indent":[1,1,1,1,1,1,1,1]}},{"type":"heading","depth":3,"children":[{"type":"text","value":"Example-3: Write a C++ program to illustrate multiple catch statement in single try block.","position":{"start":{"line":147,"column":5,"offset":6528},"end":{"line":147,"column":95,"offset":6618},"indent":[]}}],"position":{"start":{"line":147,"column":1,"offset":6524},"end":{"line":147,"column":95,"offset":6618},"indent":[]}},{"type":"code","lang":"js","meta":null,"value":"//Write a C++ program to illustrate multiple catch statement in single try block.\n#include<iostream>\nusing namespace std;\nint main( )\n    {\n    int num=10;\n    for(num=10; num<=30; num+=10)\n        {\n        try\n            {\n            if(num==20)\n            throw(\"GOOD\");\n            else if(num<20)\n            throw num;\n            else if (num>20)\n            throw 2.25f;\n            }\n        catch(const int E)\n            {\n            cout<<\"Caught int Exception E=\"<<E<<endl;\n            }\n        catch(const char* E)\n            {\n            cout<<\"Caught string Exception E=\"<<E<<endl;\n            }\n        catch( const float E)\n            {\n            cout<<\"Caught float Exception E=\"<<E<<endl;\n            }\n        }\n    cout<<\"Outside try catch block\"<<endl;\n    }","position":{"start":{"line":148,"column":1,"offset":6620},"end":{"line":181,"column":4,"offset":7454},"indent":[1,1,1,1,1,1,1,1,1,1,1,1,1,1,1,1,1,1,1,1,1,1,1,1,1,1,1,1,1,1,1,1,1]}},{"type":"code","lang":null,"meta":null,"value":"Output:\nCaught int Exception E=10\nCaught string Exception E=GOOD\nCaught float Exception E=2.25\nOutside try catch block","position":{"start":{"line":182,"column":1,"offset":7456},"end":{"line":188,"column":4,"offset":7588},"indent":[1,1,1,1,1,1]}},{"type":"heading","depth":3,"children":[{"type":"text","value":"Example-4: Write a C++ program to illustrate array index out of bound exception.","position":{"start":{"line":189,"column":5,"offset":7594},"end":{"line":189,"column":85,"offset":7674},"indent":[]}}],"position":{"start":{"line":189,"column":1,"offset":7590},"end":{"line":189,"column":85,"offset":7674},"indent":[]}},{"type":"code","lang":"js","meta":null,"value":"//Write a C++ program to illustrate array index out of bound exception.\n#include<iostream>\nusing namespace std;\n#define S 5\nint main( )\n    {\n    int arr[S]= {1,2,3,4,5};\n    int idx;\n    void show_ele(int[ ],int);\n    cout<<\"Enter the array index\\n\";\n    cin>>idx;\n    try\n        {\n        show_ele(arr,idx);\n        }\n    catch(const char* E)\n        {\n        cout<<\"Caught an Exception\\n\";\n        cout<<E<<endl;\n        }\n    cout<<\"Out of try catch block \\n\";\n    }\nvoid show_ele(int arr[ ],int idx)\n    {\n    if(idx>=0 && idx<S)\n    cout<<\"Element at \"<<idx<<\" is \"<<arr[idx]<<endl;\n    else\n    throw(\"Array index out of bound\");\n}","position":{"start":{"line":190,"column":1,"offset":7676},"end":{"line":220,"column":4,"offset":8356},"indent":[1,1,1,1,1,1,1,1,1,1,1,1,1,1,1,1,1,1,1,1,1,1,1,1,1,1,1,1,1,1]}},{"type":"code","lang":null,"meta":null,"value":"Output:\nEnter the array index\n5\nCaught an Exception\nArray index out of bound\nOut of try catch block","position":{"start":{"line":221,"column":1,"offset":8358},"end":{"line":228,"column":4,"offset":8472},"indent":[1,1,1,1,1,1,1]}},{"type":"heading","depth":3,"children":[{"type":"text","value":"Example-5: Write a C++ program to illustrate exception handling mechanism in inheritance.","position":{"start":{"line":229,"column":5,"offset":8478},"end":{"line":229,"column":94,"offset":8567},"indent":[]}}],"position":{"start":{"line":229,"column":1,"offset":8474},"end":{"line":229,"column":94,"offset":8567},"indent":[]}},{"type":"code","lang":"js","meta":null,"value":"//Write a C++ program to illustrate exception handling mechanism in inheritance.\n#include<iostream>\nusing namespace std;\nclass demo1\n    {\n    };\nclass demo2 :public demo1\n    {\n    };\nint main( )\n    {\n    for(int i=1; i<=2; i++)\n        {\n        try\n            {\n            if(i==1)\n            throw demo1( );\n            else if(i==2)\n            throw demo2( );\n            }\n        catch(demo1 d1)\n        {\n        cout<<\"Caught exception of demo1 class \\n\";\n        }\n        catch(demo2 d2)\n        {\n        cout<<\"Caught exception of demo2 class \\n\";\n        }\n        }\n    }","position":{"start":{"line":230,"column":1,"offset":8569},"end":{"line":261,"column":4,"offset":9201},"indent":[1,1,1,1,1,1,1,1,1,1,1,1,1,1,1,1,1,1,1,1,1,1,1,1,1,1,1,1,1,1,1]}},{"type":"code","lang":null,"meta":null,"value":"Output:\nCaught exception of demo1 class\nCaught exception of demo1 class","position":{"start":{"line":262,"column":1,"offset":9203},"end":{"line":266,"column":4,"offset":9286},"indent":[1,1,1,1]}},{"type":"heading","depth":3,"children":[{"type":"text","value":"Example-6: Write a C++ program to illustrate exception handling mechanism in constructor.","position":{"start":{"line":267,"column":5,"offset":9292},"end":{"line":267,"column":94,"offset":9381},"indent":[]}}],"position":{"start":{"line":267,"column":1,"offset":9288},"end":{"line":267,"column":94,"offset":9381},"indent":[]}},{"type":"code","lang":"js","meta":null,"value":"//Write a C++ program to illustrate exception handling mechanism in constructor.\n#include<iostream>\nusing namespace std;\nclass demo\n    {\n    int num;\n    public :\n    demo( )\n        {\n        try\n            {\n            throw 25;\n            }\n        catch(int E)\n            {\n            cout<<\"Exception caught \\n\";\n            num=E;\n            }\n        }\n    void show( )\n        {\n        cout<<\"num=\"<<num<<endl;\n        }\n    };\nint main( )\n    {\n    demo d;\n    d.show( );\n    }","position":{"start":{"line":268,"column":1,"offset":9383},"end":{"line":298,"column":4,"offset":9917},"indent":[1,1,1,1,1,1,1,1,1,1,1,1,1,1,1,1,1,1,1,1,1,1,1,1,1,1,1,1,1,1]}},{"type":"code","lang":null,"meta":null,"value":"Output:\nException caught\nnum=25","position":{"start":{"line":299,"column":1,"offset":9919},"end":{"line":303,"column":4,"offset":9962},"indent":[1,1,1,1]}},{"type":"heading","depth":3,"children":[{"type":"text","value":"Example-7: Write a C++ program to illustrate catching all types of exception in single catch block.","position":{"start":{"line":304,"column":5,"offset":9968},"end":{"line":304,"column":104,"offset":10067},"indent":[]}}],"position":{"start":{"line":304,"column":1,"offset":9964},"end":{"line":304,"column":104,"offset":10067},"indent":[]}},{"type":"code","lang":"js","meta":null,"value":"//Write a C++ program to illustrate catching all types of exception in single catch block.\n#include<iostream>\nusing namespace std;\nint main( )\n    {\n    int num = 10;\n    for(num=10; num<=30; num+=10)\n        {\n        try\n            {\n            if(num==20)\n            throw(\"Good\");\n            else if(num<20)\n            throw num;\n            else if(num>20)\n            throw 2.25f;\n            }\n        catch(...)\n            {\n            cout<<\"Caught an Exception \\n\";\n            }\n        cout<<\"Outside try catch block\\n\";\n        }\n    }","position":{"start":{"line":305,"column":1,"offset":10069},"end":{"line":330,"column":4,"offset":10659},"indent":[1,1,1,1,1,1,1,1,1,1,1,1,1,1,1,1,1,1,1,1,1,1,1,1,1]}},{"type":"code","lang":null,"meta":null,"value":"Output:\nCaught an Exception\nOutside try catch block\nCaught an Exception\nOutside try catch block\nCaught an Exception\nOutside try catch block","position":{"start":{"line":331,"column":1,"offset":10661},"end":{"line":339,"column":4,"offset":10816},"indent":[1,1,1,1,1,1,1,1]}},{"type":"export","value":"export const _frontmatter = {\"title\":\"Exception Handling in Cplusplus\",\"category\":\"Cplusplus Tutorial\",\"author\":\"Anonymous\",\"tags\":[\"#C++\",\"#tutorial\"],\"date\":\"2021-01-01T00:00:00.000Z\",\"thumbnailText\":\"C++ Tutorial-31\"}","position":{"start":{"line":342,"column":1,"offset":10820},"end":{"line":342,"column":221,"offset":11040},"indent":[]}}],"position":{"start":{"line":1,"column":1,"offset":0},"end":{"line":342,"column":221,"offset":11040}}},"scopeImports":["import * as React from 'react'"],"scopeIdentifiers":["React"],"body":"var _excluded = [\"components\"];\n\nfunction _extends() { _extends = Object.assign || function (target) { for (var i = 1; i < arguments.length; i++) { var source = arguments[i]; for (var key in source) { if (Object.prototype.hasOwnProperty.call(source, key)) { target[key] = source[key]; } } } return target; }; return _extends.apply(this, arguments); }\n\nfunction _objectWithoutProperties(source, excluded) { if (source == null) return {}; var target = _objectWithoutPropertiesLoose(source, excluded); var key, i; if (Object.getOwnPropertySymbols) { var sourceSymbolKeys = Object.getOwnPropertySymbols(source); for (i = 0; i < sourceSymbolKeys.length; i++) { key = sourceSymbolKeys[i]; if (excluded.indexOf(key) >= 0) continue; if (!Object.prototype.propertyIsEnumerable.call(source, key)) continue; target[key] = source[key]; } } return target; }\n\nfunction _objectWithoutPropertiesLoose(source, excluded) { if (source == null) return {}; var target = {}; var sourceKeys = Object.keys(source); var key, i; for (i = 0; i < sourceKeys.length; i++) { key = sourceKeys[i]; if (excluded.indexOf(key) >= 0) continue; target[key] = source[key]; } return target; }\n\n/* @jsxRuntime classic */\n\n/* @jsx mdx */\nvar _frontmatter = {\n  \"title\": \"Exception Handling in Cplusplus\",\n  \"category\": \"Cplusplus Tutorial\",\n  \"author\": \"Anonymous\",\n  \"tags\": [\"#C++\", \"#tutorial\"],\n  \"date\": \"2021-01-01T00:00:00.000Z\",\n  \"thumbnailText\": \"C++ Tutorial-31\"\n};\nvar layoutProps = {\n  _frontmatter: _frontmatter\n};\nvar MDXLayout = \"wrapper\";\nreturn function MDXContent(_ref) {\n  var components = _ref.components,\n      props = _objectWithoutProperties(_ref, _excluded);\n\n  return mdx(MDXLayout, _extends({}, layoutProps, props, {\n    components: components,\n    mdxType: \"MDXLayout\"\n  }), mdx(\"h2\", {\n    \"id\": \"exception-handling-in-c\"\n  }, \"Exception Handling in C++\"), mdx(\"p\", null, \"In C++ errors can be divided into two categories compile time errors and run time errors. Compile time errors are syntactic errors which occurs during the writing of the program. Most common examples of compile time errors are missing semicolon, missing comma, missing double quotes, etc.\"), mdx(\"ul\", null, mdx(\"li\", {\n    parentName: \"ul\"\n  }, \"They occurs mainly due to poor understanding of language or writing program without proper concentration to the program.\"), mdx(\"li\", {\n    parentName: \"ul\"\n  }, \"There are logical errors which are mainly due to improper understanding of the program logic by the programmer.\"), mdx(\"li\", {\n    parentName: \"ul\"\n  }, \"Logical errors cause the unexpected or unwanted output.\"), mdx(\"li\", {\n    parentName: \"ul\"\n  }, \"Exceptions are runtime errors which a programmer usually does not except.\"), mdx(\"li\", {\n    parentName: \"ul\"\n  }, \"They occurs accidentally which may result in abnormal termination of the program.\"), mdx(\"li\", {\n    parentName: \"ul\"\n  }, \"C++ provides exception handling mechanism which can be used to trap this exception and running programs smoothly after catching the exception.\"), mdx(\"li\", {\n    parentName: \"ul\"\n  }, \"Common examples of exceptions are division by zero, opening file which does not exist, insufficient memory, violating array bounds, etc.\")), mdx(\"h2\", {\n    \"id\": \"exception-handling\"\n  }, \"Exception Handling\"), mdx(\"ul\", null, mdx(\"li\", {\n    parentName: \"ul\"\n  }, mdx(\"p\", {\n    parentName: \"li\"\n  }, \"Exception handling is the process to handle the exception if generated by the program at run time. The aim of exception handling is to write code which passes exception generated to a routine which can handle the exception and can take suitable action. Any exception handling mechanism must have the following steps:\"), mdx(\"ul\", {\n    parentName: \"li\"\n  }, mdx(\"li\", {\n    parentName: \"ul\"\n  }, \"Step 1 : Writing exception class (optional).\"), mdx(\"li\", {\n    parentName: \"ul\"\n  }, \"Step 2 : Writing try block.\"), mdx(\"li\", {\n    parentName: \"ul\"\n  }, \"Step 3 : Throwing an exception.\"), mdx(\"li\", {\n    parentName: \"ul\"\n  }, \"Step 4 : Catching and handling the exception thrown.\")))), mdx(\"h2\", {\n    \"id\": \"important-notes-regarding-exception-handling\"\n  }, \"Important Notes Regarding Exception Handling\"), mdx(\"ul\", null, mdx(\"li\", {\n    parentName: \"ul\"\n  }, \"Exception is run-time error which may occur in the program\"), mdx(\"li\", {\n    parentName: \"ul\"\n  }, \"An exception if not handled may terminate the program abnormally.\"), mdx(\"li\", {\n    parentName: \"ul\"\n  }, \"To deal with exception, try-catch blocks are used.\"), mdx(\"li\", {\n    parentName: \"ul\"\n  }, \"An exception in programming term is considered an object which is thrown.\"), mdx(\"li\", {\n    parentName: \"ul\"\n  }, \"Any program code or function which may generate exception is placed in the try block. The exception is thrown by using keyword throw.\"), mdx(\"li\", {\n    parentName: \"ul\"\n  }, \"For one try block there may be multiple catch block.\"), mdx(\"li\", {\n    parentName: \"ul\"\n  }, \"An exception can be rethrown in case of nesting of try-catch blocks. To rethrown an exception, we simply write throw;\"), mdx(\"li\", {\n    parentName: \"ul\"\n  }, \"A function can specify what type of exception can be thrown by specifying in the function declaration.\"), mdx(\"li\", {\n    parentName: \"ul\"\n  }, \"Objects of user defined classes as exception can also be thrown.\"), mdx(\"li\", {\n    parentName: \"ul\"\n  }, \"The expression catch (\\u2026) can be used to catch all types of exceptions.\")), mdx(\"h2\", {\n    \"id\": \"the-try-block\"\n  }, \"The try Block\"), mdx(\"ul\", null, mdx(\"li\", {\n    parentName: \"ul\"\n  }, mdx(\"p\", {\n    parentName: \"li\"\n  }, \"The exception is to be thrown to be written in the try block. Whenever an exception is generated in the try block, it is thrown.\")), mdx(\"li\", {\n    parentName: \"ul\"\n  }, mdx(\"p\", {\n    parentName: \"li\"\n  }, \"An exception is an object so we can say that an exception object is thrown.\")), mdx(\"li\", {\n    parentName: \"ul\"\n  }, mdx(\"p\", {\n    parentName: \"li\"\n  }, \"The throw keyword is used for throwing an exception.\")), mdx(\"li\", {\n    parentName: \"ul\"\n  }, mdx(\"p\", {\n    parentName: \"li\"\n  }, \"The usual practice of using the throw statement is as : throw exception;\")), mdx(\"li\", {\n    parentName: \"ul\"\n  }, mdx(\"p\", {\n    parentName: \"li\"\n  }, \"For throwing an exception and simply throw; For re-throwing an exception.\"))), mdx(\"pre\", null, mdx(\"code\", {\n    parentName: \"pre\",\n    \"className\": \"language-js\"\n  }, \"The syntax of try block is as shown :\\ntry\\n    {\\n    statements;\\n    statements;\\n    statements;\\n    throw exception;\\n    }\\n\")), mdx(\"h2\", {\n    \"id\": \"the-catch-block\"\n  }, \"The catch Block\"), mdx(\"ul\", null, mdx(\"li\", {\n    parentName: \"ul\"\n  }, \"An exception thrown by try block is caught by the catch block. A try block must have at least one catch, though there can be many catch block for catching different types of exceptions. A catch block must have a try block prior written which will throw an exception. The catch block is used as :\")), mdx(\"pre\", null, mdx(\"code\", {\n    parentName: \"pre\",\n    \"className\": \"language-js\"\n  }, \"try\\n    {\\n    statements;\\n    statements;\\n    statements;\\n    throw exception;\\n    }\\ncatch (object or argument)\\n    {\\n    statements for handling the exception;\\n    }\\n\")), mdx(\"ul\", null, mdx(\"li\", {\n    parentName: \"ul\"\n  }, \"The catch block catches any exception thrown by the try block.\"), mdx(\"li\", {\n    parentName: \"ul\"\n  }, \"If exception thrown matches with the argument or object in the block, the statements written within the catch block and we say that exception thrown by try block was caught successfully by the catch block.\"), mdx(\"li\", {\n    parentName: \"ul\"\n  }, \"After the successful execution of the catch block statements any statements following the catch block will be executed.\"), mdx(\"li\", {\n    parentName: \"ul\"\n  }, \"If argument does not match with the exception thrown, catch couldn\\u2019t handle it and this may results in abnormal program termination.\")), mdx(\"h2\", {\n    \"id\": \"exception-handling-mechanism\"\n  }, \"Exception Handling Mechanism\"), mdx(\"ul\", null, mdx(\"li\", {\n    parentName: \"ul\"\n  }, mdx(\"p\", {\n    parentName: \"li\"\n  }, \"The try, throw and catch all together provide exception handling mechanism in C++.\")), mdx(\"li\", {\n    parentName: \"ul\"\n  }, mdx(\"p\", {\n    parentName: \"li\"\n  }, \"The exception is generated by the throw keyword which is written in the try block.\")), mdx(\"li\", {\n    parentName: \"ul\"\n  }, mdx(\"p\", {\n    parentName: \"li\"\n  }, \"Any exception generated within this try block is thrown using this throw keyword. Immediately following the try block, catch block is written.\")), mdx(\"li\", {\n    parentName: \"ul\"\n  }, mdx(\"p\", {\n    parentName: \"li\"\n  }, \"As soon as some run time errors occurs an exception is thrown by the try block using throw which informs the catch block that an error has occurred in the try block.\")), mdx(\"li\", {\n    parentName: \"ul\"\n  }, mdx(\"p\", {\n    parentName: \"li\"\n  }, \"This try block is also known as exception generated block. The catch block is responsible for catching the execution thrown by the try block.\")), mdx(\"li\", {\n    parentName: \"ul\"\n  }, mdx(\"p\", {\n    parentName: \"li\"\n  }, \"When try throw an exception, the control of the program passes to the catch block and if argument matches as explained earlier, exception is caught.\")), mdx(\"li\", {\n    parentName: \"ul\"\n  }, mdx(\"p\", {\n    parentName: \"li\"\n  }, \"In case no exception is thrown the catch block is ignored and control passes to the next statement after the catch block.\"))), mdx(\"h3\", {\n    \"id\": \"example-1-write-a-c-program-to-illustrate-division-by-zero-exception\"\n  }, \"Example-1: Write a C++ program to illustrate division by zero exception.\"), mdx(\"pre\", null, mdx(\"code\", {\n    parentName: \"pre\",\n    \"className\": \"language-js\"\n  }, \"//Write a C++ program to illustrate division by zero exception.\\n#include<iostream>\\nusing namespace std;\\nint main( )\\n    {\\n    float x,y;\\n    cout<<\\\"Enter two numbers\\\\n\\\";\\n    cin>>x>>y;\\n    try\\n        {\\n        if(y!=0)\\n        cout<<\\\"Div=\\\"<<x/y<<endl;\\n        else\\n        throw(y);\\n        }\\n    catch(float E)\\n        {\\n        cout<<\\\"Caught an Exception \\\\n\\\";\\n        cout<<\\\"y=\\\"<<y<<endl;\\n        }\\n    cout<<\\\"Out of try catch block \\\\n\\\";\\n    }\\n\")), mdx(\"pre\", null, mdx(\"code\", {\n    parentName: \"pre\"\n  }, \"Output:\\nEnter two numbers\\n20\\n0\\nCaught an Exception\\ny=0\\nOut of try catch block\\n\")), mdx(\"h3\", {\n    \"id\": \"example-2-write-a-c-program-to-illustrate-exception-handling-in-subtraction-of-two-number-a-and-b-where-ab\"\n  }, \"Example-2: Write a C++ program to illustrate exception handling in subtraction of two number a and b where a>b.\"), mdx(\"pre\", null, mdx(\"code\", {\n    parentName: \"pre\",\n    \"className\": \"language-js\"\n  }, \"// Write a C++ program to illustrate exception handling in subtraction of two number a and b where a>b.\\n#include<iostream>\\nusing namespace std;\\nint main( )\\n    {\\n    int x,y;\\n    bool m;\\n    cout<<\\\"Enter two numbers \\\\n\\\";\\n    cin>>x>>y;\\n    m=x>y ?true :false;\\n    try\\n        {\\n        if(m==true)\\n        cout<<\\\"Subtraction=\\\"<<x-y<<endl;\\n        else\\n        throw(\\\"subtraction not possible\\\");\\n        }\\n    catch(const char* E)\\n        {\\n        cout<<\\\"Caught an Exception\\\\n\\\";\\n        cout<<E<<endl;\\n        }\\n    cout<<\\\"Out of try catch block\\\\n\\\";\\n    }\\n\")), mdx(\"pre\", null, mdx(\"code\", {\n    parentName: \"pre\"\n  }, \"Output:\\nEnter two numbers\\n20\\n30\\nCaught an Exception\\nsubtraction not possible\\nOut of try catch block\\n\")), mdx(\"h3\", {\n    \"id\": \"example-3-write-a-c-program-to-illustrate-multiple-catch-statement-in-single-try-block\"\n  }, \"Example-3: Write a C++ program to illustrate multiple catch statement in single try block.\"), mdx(\"pre\", null, mdx(\"code\", {\n    parentName: \"pre\",\n    \"className\": \"language-js\"\n  }, \"//Write a C++ program to illustrate multiple catch statement in single try block.\\n#include<iostream>\\nusing namespace std;\\nint main( )\\n    {\\n    int num=10;\\n    for(num=10; num<=30; num+=10)\\n        {\\n        try\\n            {\\n            if(num==20)\\n            throw(\\\"GOOD\\\");\\n            else if(num<20)\\n            throw num;\\n            else if (num>20)\\n            throw 2.25f;\\n            }\\n        catch(const int E)\\n            {\\n            cout<<\\\"Caught int Exception E=\\\"<<E<<endl;\\n            }\\n        catch(const char* E)\\n            {\\n            cout<<\\\"Caught string Exception E=\\\"<<E<<endl;\\n            }\\n        catch( const float E)\\n            {\\n            cout<<\\\"Caught float Exception E=\\\"<<E<<endl;\\n            }\\n        }\\n    cout<<\\\"Outside try catch block\\\"<<endl;\\n    }\\n\")), mdx(\"pre\", null, mdx(\"code\", {\n    parentName: \"pre\"\n  }, \"Output:\\nCaught int Exception E=10\\nCaught string Exception E=GOOD\\nCaught float Exception E=2.25\\nOutside try catch block\\n\")), mdx(\"h3\", {\n    \"id\": \"example-4-write-a-c-program-to-illustrate-array-index-out-of-bound-exception\"\n  }, \"Example-4: Write a C++ program to illustrate array index out of bound exception.\"), mdx(\"pre\", null, mdx(\"code\", {\n    parentName: \"pre\",\n    \"className\": \"language-js\"\n  }, \"//Write a C++ program to illustrate array index out of bound exception.\\n#include<iostream>\\nusing namespace std;\\n#define S 5\\nint main( )\\n    {\\n    int arr[S]= {1,2,3,4,5};\\n    int idx;\\n    void show_ele(int[ ],int);\\n    cout<<\\\"Enter the array index\\\\n\\\";\\n    cin>>idx;\\n    try\\n        {\\n        show_ele(arr,idx);\\n        }\\n    catch(const char* E)\\n        {\\n        cout<<\\\"Caught an Exception\\\\n\\\";\\n        cout<<E<<endl;\\n        }\\n    cout<<\\\"Out of try catch block \\\\n\\\";\\n    }\\nvoid show_ele(int arr[ ],int idx)\\n    {\\n    if(idx>=0 && idx<S)\\n    cout<<\\\"Element at \\\"<<idx<<\\\" is \\\"<<arr[idx]<<endl;\\n    else\\n    throw(\\\"Array index out of bound\\\");\\n}\\n\")), mdx(\"pre\", null, mdx(\"code\", {\n    parentName: \"pre\"\n  }, \"Output:\\nEnter the array index\\n5\\nCaught an Exception\\nArray index out of bound\\nOut of try catch block\\n\")), mdx(\"h3\", {\n    \"id\": \"example-5-write-a-c-program-to-illustrate-exception-handling-mechanism-in-inheritance\"\n  }, \"Example-5: Write a C++ program to illustrate exception handling mechanism in inheritance.\"), mdx(\"pre\", null, mdx(\"code\", {\n    parentName: \"pre\",\n    \"className\": \"language-js\"\n  }, \"//Write a C++ program to illustrate exception handling mechanism in inheritance.\\n#include<iostream>\\nusing namespace std;\\nclass demo1\\n    {\\n    };\\nclass demo2 :public demo1\\n    {\\n    };\\nint main( )\\n    {\\n    for(int i=1; i<=2; i++)\\n        {\\n        try\\n            {\\n            if(i==1)\\n            throw demo1( );\\n            else if(i==2)\\n            throw demo2( );\\n            }\\n        catch(demo1 d1)\\n        {\\n        cout<<\\\"Caught exception of demo1 class \\\\n\\\";\\n        }\\n        catch(demo2 d2)\\n        {\\n        cout<<\\\"Caught exception of demo2 class \\\\n\\\";\\n        }\\n        }\\n    }\\n\")), mdx(\"pre\", null, mdx(\"code\", {\n    parentName: \"pre\"\n  }, \"Output:\\nCaught exception of demo1 class\\nCaught exception of demo1 class\\n\")), mdx(\"h3\", {\n    \"id\": \"example-6-write-a-c-program-to-illustrate-exception-handling-mechanism-in-constructor\"\n  }, \"Example-6: Write a C++ program to illustrate exception handling mechanism in constructor.\"), mdx(\"pre\", null, mdx(\"code\", {\n    parentName: \"pre\",\n    \"className\": \"language-js\"\n  }, \"//Write a C++ program to illustrate exception handling mechanism in constructor.\\n#include<iostream>\\nusing namespace std;\\nclass demo\\n    {\\n    int num;\\n    public :\\n    demo( )\\n        {\\n        try\\n            {\\n            throw 25;\\n            }\\n        catch(int E)\\n            {\\n            cout<<\\\"Exception caught \\\\n\\\";\\n            num=E;\\n            }\\n        }\\n    void show( )\\n        {\\n        cout<<\\\"num=\\\"<<num<<endl;\\n        }\\n    };\\nint main( )\\n    {\\n    demo d;\\n    d.show( );\\n    }\\n\")), mdx(\"pre\", null, mdx(\"code\", {\n    parentName: \"pre\"\n  }, \"Output:\\nException caught\\nnum=25\\n\")), mdx(\"h3\", {\n    \"id\": \"example-7-write-a-c-program-to-illustrate-catching-all-types-of-exception-in-single-catch-block\"\n  }, \"Example-7: Write a C++ program to illustrate catching all types of exception in single catch block.\"), mdx(\"pre\", null, mdx(\"code\", {\n    parentName: \"pre\",\n    \"className\": \"language-js\"\n  }, \"//Write a C++ program to illustrate catching all types of exception in single catch block.\\n#include<iostream>\\nusing namespace std;\\nint main( )\\n    {\\n    int num = 10;\\n    for(num=10; num<=30; num+=10)\\n        {\\n        try\\n            {\\n            if(num==20)\\n            throw(\\\"Good\\\");\\n            else if(num<20)\\n            throw num;\\n            else if(num>20)\\n            throw 2.25f;\\n            }\\n        catch(...)\\n            {\\n            cout<<\\\"Caught an Exception \\\\n\\\";\\n            }\\n        cout<<\\\"Outside try catch block\\\\n\\\";\\n        }\\n    }\\n\")), mdx(\"pre\", null, mdx(\"code\", {\n    parentName: \"pre\"\n  }, \"Output:\\nCaught an Exception\\nOutside try catch block\\nCaught an Exception\\nOutside try catch block\\nCaught an Exception\\nOutside try catch block\\n\")));\n}\n;\nMDXContent.isMDXComponent = true;","rawMDXOutput":"/* @jsx mdx */\nimport { mdx } from '@mdx-js/react';\n/* @jsxRuntime classic */\n/* @jsx mdx */\n\nexport const _frontmatter = {\n  \"title\": \"Exception Handling in Cplusplus\",\n  \"category\": \"Cplusplus Tutorial\",\n  \"author\": \"Anonymous\",\n  \"tags\": [\"#C++\", \"#tutorial\"],\n  \"date\": \"2021-01-01T00:00:00.000Z\",\n  \"thumbnailText\": \"C++ Tutorial-31\"\n};\n\nconst layoutProps = {\n  _frontmatter\n};\nconst MDXLayout = \"wrapper\"\nexport default function MDXContent({\n  components,\n  ...props\n}) {\n  return <MDXLayout {...layoutProps} {...props} components={components} mdxType=\"MDXLayout\">\n    <h2 {...{\n      \"id\": \"exception-handling-in-c\"\n    }}>{`Exception Handling in C++`}</h2>\n    <p>{`In C++ errors can be divided into two categories compile time errors and run time errors. Compile time errors are syntactic errors which occurs during the writing of the program. Most common examples of compile time errors are missing semicolon, missing comma, missing double quotes, etc.`}</p>\n    <ul>\n      <li parentName=\"ul\">{`They occurs mainly due to poor understanding of language or writing program without proper concentration to the program.`}</li>\n      <li parentName=\"ul\">{`There are logical errors which are mainly due to improper understanding of the program logic by the programmer.`}</li>\n      <li parentName=\"ul\">{`Logical errors cause the unexpected or unwanted output.`}</li>\n      <li parentName=\"ul\">{`Exceptions are runtime errors which a programmer usually does not except.`}</li>\n      <li parentName=\"ul\">{`They occurs accidentally which may result in abnormal termination of the program.`}</li>\n      <li parentName=\"ul\">{`C++ provides exception handling mechanism which can be used to trap this exception and running programs smoothly after catching the exception.`}</li>\n      <li parentName=\"ul\">{`Common examples of exceptions are division by zero, opening file which does not exist, insufficient memory, violating array bounds, etc.`}</li>\n    </ul>\n    <h2 {...{\n      \"id\": \"exception-handling\"\n    }}>{`Exception Handling`}</h2>\n    <ul>\n      <li parentName=\"ul\">\n        <p parentName=\"li\">{`Exception handling is the process to handle the exception if generated by the program at run time. The aim of exception handling is to write code which passes exception generated to a routine which can handle the exception and can take suitable action. Any exception handling mechanism must have the following steps:`}</p>\n        <ul parentName=\"li\">\n          <li parentName=\"ul\">{`Step 1 : Writing exception class (optional).`}</li>\n          <li parentName=\"ul\">{`Step 2 : Writing try block.`}</li>\n          <li parentName=\"ul\">{`Step 3 : Throwing an exception.`}</li>\n          <li parentName=\"ul\">{`Step 4 : Catching and handling the exception thrown.`}</li>\n        </ul>\n      </li>\n    </ul>\n    <h2 {...{\n      \"id\": \"important-notes-regarding-exception-handling\"\n    }}>{`Important Notes Regarding Exception Handling`}</h2>\n    <ul>\n      <li parentName=\"ul\">{`Exception is run-time error which may occur in the program`}</li>\n      <li parentName=\"ul\">{`An exception if not handled may terminate the program abnormally.`}</li>\n      <li parentName=\"ul\">{`To deal with exception, try-catch blocks are used.`}</li>\n      <li parentName=\"ul\">{`An exception in programming term is considered an object which is thrown.`}</li>\n      <li parentName=\"ul\">{`Any program code or function which may generate exception is placed in the try block. The exception is thrown by using keyword throw.`}</li>\n      <li parentName=\"ul\">{`For one try block there may be multiple catch block.`}</li>\n      <li parentName=\"ul\">{`An exception can be rethrown in case of nesting of try-catch blocks. To rethrown an exception, we simply write throw;`}</li>\n      <li parentName=\"ul\">{`A function can specify what type of exception can be thrown by specifying in the function declaration.`}</li>\n      <li parentName=\"ul\">{`Objects of user defined classes as exception can also be thrown.`}</li>\n      <li parentName=\"ul\">{`The expression catch (…) can be used to catch all types of exceptions.`}</li>\n    </ul>\n    <h2 {...{\n      \"id\": \"the-try-block\"\n    }}>{`The try Block`}</h2>\n    <ul>\n      <li parentName=\"ul\">\n        <p parentName=\"li\">{`The exception is to be thrown to be written in the try block. Whenever an exception is generated in the try block, it is thrown.`}</p>\n      </li>\n      <li parentName=\"ul\">\n        <p parentName=\"li\">{`An exception is an object so we can say that an exception object is thrown.`}</p>\n      </li>\n      <li parentName=\"ul\">\n        <p parentName=\"li\">{`The throw keyword is used for throwing an exception.`}</p>\n      </li>\n      <li parentName=\"ul\">\n        <p parentName=\"li\">{`The usual practice of using the throw statement is as : throw exception;`}</p>\n      </li>\n      <li parentName=\"ul\">\n        <p parentName=\"li\">{`For throwing an exception and simply throw; For re-throwing an exception.`}</p>\n      </li>\n    </ul>\n    <pre><code parentName=\"pre\" {...{\n        \"className\": \"language-js\"\n      }}>{`The syntax of try block is as shown :\ntry\n    {\n    statements;\n    statements;\n    statements;\n    throw exception;\n    }\n`}</code></pre>\n    <h2 {...{\n      \"id\": \"the-catch-block\"\n    }}>{`The catch Block`}</h2>\n    <ul>\n      <li parentName=\"ul\">{`An exception thrown by try block is caught by the catch block. A try block must have at least one catch, though there can be many catch block for catching different types of exceptions. A catch block must have a try block prior written which will throw an exception. The catch block is used as :`}</li>\n    </ul>\n    <pre><code parentName=\"pre\" {...{\n        \"className\": \"language-js\"\n      }}>{`try\n    {\n    statements;\n    statements;\n    statements;\n    throw exception;\n    }\ncatch (object or argument)\n    {\n    statements for handling the exception;\n    }\n`}</code></pre>\n    <ul>\n      <li parentName=\"ul\">{`The catch block catches any exception thrown by the try block.`}</li>\n      <li parentName=\"ul\">{`If exception thrown matches with the argument or object in the block, the statements written within the catch block and we say that exception thrown by try block was caught successfully by the catch block.`}</li>\n      <li parentName=\"ul\">{`After the successful execution of the catch block statements any statements following the catch block will be executed.`}</li>\n      <li parentName=\"ul\">{`If argument does not match with the exception thrown, catch couldn’t handle it and this may results in abnormal program termination.`}</li>\n    </ul>\n    <h2 {...{\n      \"id\": \"exception-handling-mechanism\"\n    }}>{`Exception Handling Mechanism`}</h2>\n    <ul>\n      <li parentName=\"ul\">\n        <p parentName=\"li\">{`The try, throw and catch all together provide exception handling mechanism in C++.`}</p>\n      </li>\n      <li parentName=\"ul\">\n        <p parentName=\"li\">{`The exception is generated by the throw keyword which is written in the try block.`}</p>\n      </li>\n      <li parentName=\"ul\">\n        <p parentName=\"li\">{`Any exception generated within this try block is thrown using this throw keyword. Immediately following the try block, catch block is written.`}</p>\n      </li>\n      <li parentName=\"ul\">\n        <p parentName=\"li\">{`As soon as some run time errors occurs an exception is thrown by the try block using throw which informs the catch block that an error has occurred in the try block.`}</p>\n      </li>\n      <li parentName=\"ul\">\n        <p parentName=\"li\">{`This try block is also known as exception generated block. The catch block is responsible for catching the execution thrown by the try block.`}</p>\n      </li>\n      <li parentName=\"ul\">\n        <p parentName=\"li\">{`When try throw an exception, the control of the program passes to the catch block and if argument matches as explained earlier, exception is caught.`}</p>\n      </li>\n      <li parentName=\"ul\">\n        <p parentName=\"li\">{`In case no exception is thrown the catch block is ignored and control passes to the next statement after the catch block.`}</p>\n      </li>\n    </ul>\n    <h3 {...{\n      \"id\": \"example-1-write-a-c-program-to-illustrate-division-by-zero-exception\"\n    }}>{`Example-1: Write a C++ program to illustrate division by zero exception.`}</h3>\n    <pre><code parentName=\"pre\" {...{\n        \"className\": \"language-js\"\n      }}>{`//Write a C++ program to illustrate division by zero exception.\n#include<iostream>\nusing namespace std;\nint main( )\n    {\n    float x,y;\n    cout<<\"Enter two numbers\\\\n\";\n    cin>>x>>y;\n    try\n        {\n        if(y!=0)\n        cout<<\"Div=\"<<x/y<<endl;\n        else\n        throw(y);\n        }\n    catch(float E)\n        {\n        cout<<\"Caught an Exception \\\\n\";\n        cout<<\"y=\"<<y<<endl;\n        }\n    cout<<\"Out of try catch block \\\\n\";\n    }\n`}</code></pre>\n    <pre><code parentName=\"pre\" {...{}}>{`Output:\nEnter two numbers\n20\n0\nCaught an Exception\ny=0\nOut of try catch block\n`}</code></pre>\n    <h3 {...{\n      \"id\": \"example-2-write-a-c-program-to-illustrate-exception-handling-in-subtraction-of-two-number-a-and-b-where-ab\"\n    }}>{`Example-2: Write a C++ program to illustrate exception handling in subtraction of two number a and b where a>b.`}</h3>\n    <pre><code parentName=\"pre\" {...{\n        \"className\": \"language-js\"\n      }}>{`// Write a C++ program to illustrate exception handling in subtraction of two number a and b where a>b.\n#include<iostream>\nusing namespace std;\nint main( )\n    {\n    int x,y;\n    bool m;\n    cout<<\"Enter two numbers \\\\n\";\n    cin>>x>>y;\n    m=x>y ?true :false;\n    try\n        {\n        if(m==true)\n        cout<<\"Subtraction=\"<<x-y<<endl;\n        else\n        throw(\"subtraction not possible\");\n        }\n    catch(const char* E)\n        {\n        cout<<\"Caught an Exception\\\\n\";\n        cout<<E<<endl;\n        }\n    cout<<\"Out of try catch block\\\\n\";\n    }\n`}</code></pre>\n    <pre><code parentName=\"pre\" {...{}}>{`Output:\nEnter two numbers\n20\n30\nCaught an Exception\nsubtraction not possible\nOut of try catch block\n`}</code></pre>\n    <h3 {...{\n      \"id\": \"example-3-write-a-c-program-to-illustrate-multiple-catch-statement-in-single-try-block\"\n    }}>{`Example-3: Write a C++ program to illustrate multiple catch statement in single try block.`}</h3>\n    <pre><code parentName=\"pre\" {...{\n        \"className\": \"language-js\"\n      }}>{`//Write a C++ program to illustrate multiple catch statement in single try block.\n#include<iostream>\nusing namespace std;\nint main( )\n    {\n    int num=10;\n    for(num=10; num<=30; num+=10)\n        {\n        try\n            {\n            if(num==20)\n            throw(\"GOOD\");\n            else if(num<20)\n            throw num;\n            else if (num>20)\n            throw 2.25f;\n            }\n        catch(const int E)\n            {\n            cout<<\"Caught int Exception E=\"<<E<<endl;\n            }\n        catch(const char* E)\n            {\n            cout<<\"Caught string Exception E=\"<<E<<endl;\n            }\n        catch( const float E)\n            {\n            cout<<\"Caught float Exception E=\"<<E<<endl;\n            }\n        }\n    cout<<\"Outside try catch block\"<<endl;\n    }\n`}</code></pre>\n    <pre><code parentName=\"pre\" {...{}}>{`Output:\nCaught int Exception E=10\nCaught string Exception E=GOOD\nCaught float Exception E=2.25\nOutside try catch block\n`}</code></pre>\n    <h3 {...{\n      \"id\": \"example-4-write-a-c-program-to-illustrate-array-index-out-of-bound-exception\"\n    }}>{`Example-4: Write a C++ program to illustrate array index out of bound exception.`}</h3>\n    <pre><code parentName=\"pre\" {...{\n        \"className\": \"language-js\"\n      }}>{`//Write a C++ program to illustrate array index out of bound exception.\n#include<iostream>\nusing namespace std;\n#define S 5\nint main( )\n    {\n    int arr[S]= {1,2,3,4,5};\n    int idx;\n    void show_ele(int[ ],int);\n    cout<<\"Enter the array index\\\\n\";\n    cin>>idx;\n    try\n        {\n        show_ele(arr,idx);\n        }\n    catch(const char* E)\n        {\n        cout<<\"Caught an Exception\\\\n\";\n        cout<<E<<endl;\n        }\n    cout<<\"Out of try catch block \\\\n\";\n    }\nvoid show_ele(int arr[ ],int idx)\n    {\n    if(idx>=0 && idx<S)\n    cout<<\"Element at \"<<idx<<\" is \"<<arr[idx]<<endl;\n    else\n    throw(\"Array index out of bound\");\n}\n`}</code></pre>\n    <pre><code parentName=\"pre\" {...{}}>{`Output:\nEnter the array index\n5\nCaught an Exception\nArray index out of bound\nOut of try catch block\n`}</code></pre>\n    <h3 {...{\n      \"id\": \"example-5-write-a-c-program-to-illustrate-exception-handling-mechanism-in-inheritance\"\n    }}>{`Example-5: Write a C++ program to illustrate exception handling mechanism in inheritance.`}</h3>\n    <pre><code parentName=\"pre\" {...{\n        \"className\": \"language-js\"\n      }}>{`//Write a C++ program to illustrate exception handling mechanism in inheritance.\n#include<iostream>\nusing namespace std;\nclass demo1\n    {\n    };\nclass demo2 :public demo1\n    {\n    };\nint main( )\n    {\n    for(int i=1; i<=2; i++)\n        {\n        try\n            {\n            if(i==1)\n            throw demo1( );\n            else if(i==2)\n            throw demo2( );\n            }\n        catch(demo1 d1)\n        {\n        cout<<\"Caught exception of demo1 class \\\\n\";\n        }\n        catch(demo2 d2)\n        {\n        cout<<\"Caught exception of demo2 class \\\\n\";\n        }\n        }\n    }\n`}</code></pre>\n    <pre><code parentName=\"pre\" {...{}}>{`Output:\nCaught exception of demo1 class\nCaught exception of demo1 class\n`}</code></pre>\n    <h3 {...{\n      \"id\": \"example-6-write-a-c-program-to-illustrate-exception-handling-mechanism-in-constructor\"\n    }}>{`Example-6: Write a C++ program to illustrate exception handling mechanism in constructor.`}</h3>\n    <pre><code parentName=\"pre\" {...{\n        \"className\": \"language-js\"\n      }}>{`//Write a C++ program to illustrate exception handling mechanism in constructor.\n#include<iostream>\nusing namespace std;\nclass demo\n    {\n    int num;\n    public :\n    demo( )\n        {\n        try\n            {\n            throw 25;\n            }\n        catch(int E)\n            {\n            cout<<\"Exception caught \\\\n\";\n            num=E;\n            }\n        }\n    void show( )\n        {\n        cout<<\"num=\"<<num<<endl;\n        }\n    };\nint main( )\n    {\n    demo d;\n    d.show( );\n    }\n`}</code></pre>\n    <pre><code parentName=\"pre\" {...{}}>{`Output:\nException caught\nnum=25\n`}</code></pre>\n    <h3 {...{\n      \"id\": \"example-7-write-a-c-program-to-illustrate-catching-all-types-of-exception-in-single-catch-block\"\n    }}>{`Example-7: Write a C++ program to illustrate catching all types of exception in single catch block.`}</h3>\n    <pre><code parentName=\"pre\" {...{\n        \"className\": \"language-js\"\n      }}>{`//Write a C++ program to illustrate catching all types of exception in single catch block.\n#include<iostream>\nusing namespace std;\nint main( )\n    {\n    int num = 10;\n    for(num=10; num<=30; num+=10)\n        {\n        try\n            {\n            if(num==20)\n            throw(\"Good\");\n            else if(num<20)\n            throw num;\n            else if(num>20)\n            throw 2.25f;\n            }\n        catch(...)\n            {\n            cout<<\"Caught an Exception \\\\n\";\n            }\n        cout<<\"Outside try catch block\\\\n\";\n        }\n    }\n`}</code></pre>\n    <pre><code parentName=\"pre\" {...{}}>{`Output:\nCaught an Exception\nOutside try catch block\nCaught an Exception\nOutside try catch block\nCaught an Exception\nOutside try catch block\n`}</code></pre>\n\n    </MDXLayout>;\n}\n\n;\nMDXContent.isMDXComponent = true;"}}